Workbook

Sheet 2025期功能研发汇总表
A1: OPEX-需求名称 CAPEX-子系统 | B1: 一级模块 | C1: 二级模块 | D1: 三级模块 | E1: 功能过程 | F1: 备注 | G1: 分工 | H1: 功能项 | I1: 研发进展 | J1: 更新日期 | K1: 新菜单路径（v3.8.3） | L1: 功能操作 | M1: 界面截图 | N1: 青海发布 | O1: 青海反馈 | P1: 山东发布 | Q1: 山东反馈 | R1: 吉林发布 | S1: 吉林反馈 | T1: 天津发布 | U1: 天津反馈 | V1: 菜单/路径(完成必填)
A2: 安全风险识别与利用分析 | B2: CPE库管理 | C2: CPE文档基础管理 | D2: CPE文档基础管理 | E2: CPE文档查询 | G2: 蔡云飞 | H2: 合同功能 | I2: 联调完成 | J2: 46091 | K2: 漏洞生命周期管理/产品漏洞管理/CPE文档管理 | L2: 查询按钮 | N2: V3.8.0-beat.1 | O2: 待反馈 | P2: V3.8.0-beat.1 | Q2: 待反馈 | R2: V3.8.0-beat.1 | S2: 待反馈 | T2: V3.8.0-beat.1 | U2: ==VLOOKUP(E2,天津功能清单!E:G,3,FALSE) -> 已交付 | V2: 漏洞生命周期管理/产品漏洞管理/CPE文档管理
E3: CPE文档创建 | G3: 蔡云飞 | H3: 合同功能 | I3: 联调完成 | J3: 46091 | K3: 漏洞生命周期管理/产品漏洞管理/CPE文档管理 | L3: 创建按钮 | N3: V3.7.0(20260312) | O3: 待反馈 | P3: V3.8.0-beat.1 | Q3: 待反馈 | R3: V3.8.0-beat.1 | S3: 待反馈 | T3: V3.8.0-beat.1 | U3: ==VLOOKUP(E3,天津功能清单!E:G,3,FALSE) -> 已发布 | V3: 漏洞生命周期管理/产品漏洞管理/CPE文档管理
E4: CPE文档编辑 | G4: 蔡云飞 | H4: 合同功能 | I4: 联调完成 | J4: 46091 | K4: 漏洞生命周期管理/产品漏洞管理/CPE文档管理 | L4: 编辑按钮 | N4: V3.7.0(20260312) | O4: 待反馈 | P4: V3.8.0-beat.1 | Q4: 待反馈 | R4: V3.8.0-beat.1 | S4: 待反馈 | T4: V3.8.0-beat.1 | U4: ==VLOOKUP(E4,天津功能清单!E:G,3,FALSE) -> 已发布 | V4: 漏洞生命周期管理/产品漏洞管理/CPE文档管理
E5: CPE文档删除 | G5: 蔡云飞 | H5: 合同功能 | I5: 联调完成 | J5: 46091 | K5: 漏洞生命周期管理/产品漏洞管理/CPE文档管理 | L5: 删除按钮 | N5: V3.7.0(20260312) | O5: 待反馈 | P5: V3.8.0-beat.1 | Q5: 待反馈 | R5: V3.8.0-beat.1 | S5: 待反馈 | T5: V3.8.0-beat.1 | U5: ==VLOOKUP(E5,天津功能清单!E:G,3,FALSE) -> 已发布 | V5: 漏洞生命周期管理/产品漏洞管理/CPE文档管理
E6: CPE文档详情查询 | F6: 广东省新增功能 | G6: 蔡云飞 | H6: 合同功能 | I6: 联调完成 | J6: 46091 | K6: 漏洞生命周期管理/产品漏洞管理/CPE文档管理 | L6: 详情查询按钮 | N6: V3.7.0(20260312) | O6: 待反馈 | P6: V3.8.0-beat.1 | Q6: 待反馈 | R6: V3.8.0-beat.1 | S6: 待反馈 | T6: V3.8.0-beat.1 | U6: ==VLOOKUP(E6,天津功能清单!E:G,3,FALSE) -> #N/A | V6: 漏洞生命周期管理/产品漏洞管理/CPE文档管理
E7: CPE文档导入 | G7: 蔡云飞 | H7: 合同功能 | I7: 联调完成 | J7: 46091 | K7: 漏洞生命周期管理/产品漏洞管理/CPE文档管理 | L7: 导入按钮 | N7: V3.7.0(20260312) | O7: 待反馈 | P7: V3.8.0-beat.1 | Q7: 待反馈 | R7: V3.8.0-beat.1 | S7: 待反馈 | T7: V3.8.0-beat.1 | U7: ==VLOOKUP(E7,天津功能清单!E:G,3,FALSE) -> 已发布 | V7: 漏洞生命周期管理/产品漏洞管理/CPE文档管理
E8: CPE文档导出 | G8: 蔡云飞 | H8: 合同功能 | I8: 联调完成 | J8: 46091 | K8: 漏洞生命周期管理/产品漏洞管理/CPE文档管理 | L8: 导出按钮 | N8: V3.7.0(20260312) | O8: 待反馈 | P8: V3.8.0-beat.1 | Q8: 待反馈 | R8: V3.8.0-beat.1 | S8: 待反馈 | T8: V3.8.0-beat.1 | U8: ==VLOOKUP(E8,天津功能清单!E:G,3,FALSE) -> 已发布 | V8: 漏洞生命周期管理/产品漏洞管理/CPE文档管理
C9: CPE数据标准化校验 | D9: CPE数据标准化校验 | E9: CPE数据格式校验 | F9: 广东省删除功能 | G9: 蔡云飞 | H9: 合同功能 | I9: 联调完成 | J9: 46091 | K9: 漏洞生命周期管理/产品漏洞管理/CPE文档管理 | L9: 程序内部自动执行 | N9: V3.7.0(20260312) | O9: 待反馈 | P9: V3.8.0-beat.1 | Q9: 待反馈 | R9: V3.8.0-beat.1 | S9: 待反馈 | T9: V3.8.0-beat.1 | U9: ==VLOOKUP(E9,天津功能清单!E:G,3,FALSE) -> 已发布 | V9: 漏洞生命周期管理/产品漏洞管理/CPE文档管理
B10: VEX文档管理 | C10: VEX文档全生命周期管理 | D10: VEX文档全生命周期管理 | E10: CPE数据格式校验 | G10: 蔡云飞 | H10: 合同功能 | I10: 联调完成 | J10: 46098 | K10: 运营·深耕/产品漏洞与风险识别/VEX生命周期管理 | L10: 下载按钮 | N10: V3.8.0-beat.1 | O10: 待反馈 | P10: V3.8.0-beat.1 | Q10: 待反馈 | R10: V3.8.0-beat.1 | S10: 待反馈 | T10: V3.8.0-beat.1 | U10: ==VLOOKUP(E10,天津功能清单!E:G,3,FALSE) -> 已发布 | V10: 漏洞生命周期管理/VEX基础管理/VEX生命周期管理
E11: CISA VEX文档创建 | G11: 蔡云飞 | H11: 合同功能 | I11: 联调完成 | J11: 46098 | K11: 运营·深耕/产品漏洞与风险识别/VEX生命周期管理 | L11: 新增按钮 | N11: V3.8.0-beat.1 | O11: 待反馈 | P11: V3.8.0-beat.1 | Q11: 待反馈 | R11: V3.8.0-beat.1 | S11: 待反馈 | T11: V3.8.0-beat.1 | U11: ==VLOOKUP(E11,天津功能清单!E:G,3,FALSE) -> 已发布 | V11: 漏洞生命周期管理/VEX基础管理/VEX生命周期管理
E12: CISA VEX文档删除 | G12: 蔡云飞 | H12: 合同功能 | I12: 联调完成 | J12: 46098 | K12: 运营·深耕/产品漏洞与风险识别/VEX生命周期管理 | L12: 删除按钮 | N12: V3.8.0-beat.1 | O12: 待反馈 | P12: V3.8.0-beat.1 | Q12: 待反馈 | R12: V3.8.0-beat.1 | S12: 待反馈 | T12: V3.8.0-beat.1 | U12: ==VLOOKUP(E12,天津功能清单!E:G,3,FALSE) -> 已发布 | V12: 漏洞生命周期管理/VEX基础管理/VEX生命周期管理
E13: CISA VEX文档导入 | G13: 蔡云飞 | H13: 合同功能 | I13: 联调完成 | J13: 46098 | K13: 运营·深耕/产品漏洞与风险识别/VEX生命周期管理 | L13: 导入按钮 | N13: V3.8.0-beat.1 | O13: 待反馈 | P13: V3.8.0-beat.1 | Q13: 待反馈 | R13: V3.8.0-beat.1 | S13: 待反馈 | T13: V3.8.0-beat.1 | U13: ==VLOOKUP(E13,天津功能清单!E:G,3,FALSE) -> 已发布 | V13: 漏洞生命周期管理/VEX基础管理/VEX生命周期管理
E14: CISA VEX文档导出 | G14: 蔡云飞 | H14: 合同功能 | I14: 联调完成 | J14: 46098 | K14: 运营·深耕/产品漏洞与风险识别/VEX生命周期管理 | L14: 导出按钮 | N14: V3.8.0-beat.1 | O14: 待反馈 | P14: V3.8.0-beat.1 | Q14: 待反馈 | R14: V3.8.0-beat.1 | S14: 待反馈 | T14: V3.8.0-beat.1 | U14: ==VLOOKUP(E14,天津功能清单!E:G,3,FALSE) -> 已发布 | V14: 漏洞生命周期管理/VEX基础管理/VEX生命周期管理
E15: CISA VEX文档查看 | G15: 蔡云飞 | H15: 合同功能 | I15: 联调完成 | J15: 46098 | K15: 运营·深耕/产品漏洞与风险识别/VEX生命周期管理 | L15: 查询按钮 | N15: V3.8.0-beat.1 | O15: 待反馈 | P15: V3.8.0-beat.1 | Q15: 待反馈 | R15: V3.8.0-beat.1 | S15: 待反馈 | T15: V3.8.0-beat.1 | U15: ==VLOOKUP(E15,天津功能清单!E:G,3,FALSE) -> 已发布 | V15: 漏洞生命周期管理/VEX基础管理/VEX生命周期管理
E16: CISA VEX文档编辑 | G16: 蔡云飞 | H16: 合同功能 | I16: 联调完成 | J16: 46098 | K16: 运营·深耕/产品漏洞与风险识别/VEX生命周期管理 | L16: 修改按钮 | N16: V3.8.0-beat.1 | O16: 待反馈 | P16: V3.8.0-beat.1 | Q16: 待反馈 | R16: V3.8.0-beat.1 | S16: 待反馈 | T16: V3.8.0-beat.1 | U16: ==VLOOKUP(E16,天津功能清单!E:G,3,FALSE) -> 已发布 | V16: 漏洞生命周期管理/VEX基础管理/VEX生命周期管理
E17: CISA单个VEX文档关联产品 | G17: 蔡云飞 | H17: 合同功能 | I17: 联调完成 | J17: 46098 | K17: 运营·深耕/产品漏洞与风险识别/VEX生命周期管理 | L17: 列表关联查询展示 | N17: V3.8.0-beat.1 | O17: 待反馈 | P17: V3.8.0-beat.1 | Q17: 待反馈 | R17: V3.8.0-beat.1 | S17: 待反馈 | T17: V3.8.0-beat.1 | U17: ==VLOOKUP(E17,天津功能清单!E:G,3,FALSE) -> 已发布 | V17: 漏洞生命周期管理/VEX基础管理/VEX生命周期管理
C18: VEX文档解析展示 | D18: VEX文档解析展示 | E18: 修改基础模板 | G18: 蔡云飞 | H18: 合同功能 | I18: 联调完成 | J18: 46091 | K18: 运营·深耕/产品漏洞与风险识别/VEX文档解析管理 | L18: 修改按钮 | N18: V3.7.0(20260312) | O18: 待反馈 | P18: V3.8.0-beat.1 | Q18: 待反馈 | R18: V3.8.0-beat.1 | S18: 待反馈 | T18: V3.8.0-beat.1 | U18: ==VLOOKUP(E18,天津功能清单!E:G,3,FALSE) -> 已发布 | V18: 漏洞生命周期管理/VEX基础管理/VEX文档解析管理
E19: 删除基础模板 | G19: 蔡云飞 | H19: 合同功能 | I19: 联调完成 | J19: 46091 | K19: 运营·深耕/产品漏洞与风险识别/VEX文档解析管理 | L19: 删除按钮 | N19: V3.7.0(20260312) | O19: 待反馈 | P19: V3.8.0-beat.1 | Q19: 待反馈 | R19: V3.8.0-beat.1 | S19: 待反馈 | T19: V3.8.0-beat.1 | U19: ==VLOOKUP(E19,天津功能清单!E:G,3,FALSE) -> 已发布 | V19: 漏洞生命周期管理/VEX基础管理/VEX文档解析管理
E20: 导入基础模板 | G20: 蔡云飞 | H20: 合同功能 | I20: 联调完成 | J20: 46091 | K20: 运营·深耕/产品漏洞与风险识别/VEX文档解析管理 | L20: 导入按钮 | N20: V3.7.0(20260312) | O20: 待反馈 | P20: V3.8.0-beat.1 | Q20: 待反馈 | R20: V3.8.0-beat.1 | S20: 待反馈 | T20: V3.8.0-beat.1 | U20: ==VLOOKUP(E20,天津功能清单!E:G,3,FALSE) -> 已发布 | V20: 漏洞生命周期管理/VEX基础管理/VEX文档解析管理
E21: 导出基础模板 | G21: 蔡云飞 | H21: 合同功能 | I21: 联调完成 | J21: 46091 | K21: 运营·深耕/产品漏洞与风险识别/VEX文档解析管理 | L21: 导出按钮 | N21: V3.7.0(20260312) | O21: 待反馈 | P21: V3.8.0-beat.1 | Q21: 待反馈 | R21: V3.8.0-beat.1 | S21: 待反馈 | T21: V3.8.0-beat.1 | U21: ==VLOOKUP(E21,天津功能清单!E:G,3,FALSE) -> 已发布 | V21: 漏洞生命周期管理/VEX基础管理/VEX文档解析管理
E22: 查询基础模板 | G22: 蔡云飞 | H22: 合同功能 | I22: 联调完成 | J22: 46091 | K22: 运营·深耕/产品漏洞与风险识别/VEX文档解析管理 | L22: 查询按钮 | N22: V3.7.0(20260312) | O22: 待反馈 | P22: V3.8.0-beat.1 | Q22: 待反馈 | R22: V3.8.0-beat.1 | S22: 待反馈 | T22: V3.8.0-beat.1 | U22: ==VLOOKUP(E22,天津功能清单!E:G,3,FALSE) -> 已发布 | V22: 漏洞生命周期管理/VEX基础管理/VEX文档解析管理
E23: 添加基础模板 | G23: 蔡云飞 | H23: 合同功能 | I23: 联调完成 | J23: 46091 | K23: 运营·深耕/产品漏洞与风险识别/VEX文档解析管理 | L23: 新增按钮 | N23: V3.7.0(20260312) | O23: 待反馈 | P23: V3.8.0-beat.1 | Q23: 待反馈 | R23: V3.8.0-beat.1 | S23: 待反馈 | T23: V3.8.0-beat.1 | U23: ==VLOOKUP(E23,天津功能清单!E:G,3,FALSE) -> 已发布 | V23: 漏洞生命周期管理/VEX基础管理/VEX文档解析管理
C24: VEX合规性自动化检测 | D24: VEX合规性自动化检测 | E24: 问题文档拦截 | G24: 蔡云飞 | H24: 合同功能 | I24: 联调完成 | J24: 46091 | K24: 运营·深耕/产品漏洞与风险识别/VEX文档解析管理 | L24: 程序内部自动检测执行 | N24: V3.7.0(20260312) | O24: 待反馈 | P24: V3.8.0-beat.1 | Q24: 待反馈 | R24: V3.8.0-beat.1 | S24: 待反馈 | T24: V3.8.0-beat.1 | U24: ==VLOOKUP(E24,天津功能清单!E:G,3,FALSE) -> 已发布 | V24: 漏洞生命周期管理/VEX基础管理/VEX文档解析管理
B25: 风险组件库管理 | C25: 已知风险资产组件管理 | D25: 已知风险资产组件管理 | E25: 已知风险资产组件查询 | G25: 蔡云飞 | H25: 合同功能 | I25: 联调完成 | J25: 46091 | K25: 信息化资产管理/资产管理/已知风险资产组件管理 | L25: 查询按钮 | N25: V3.7.0(20260312) | O25: 待反馈 | P25: V3.8.0-beat.1 | Q25: 待反馈 | R25: V3.8.0-beat.1 | S25: 待反馈 | T25: V3.8.0-beat.1 | U25: ==VLOOKUP(E25,天津功能清单!E:G,3,FALSE) -> 已发布 | V25: 信息化资产管理/资产管理/已知风险资产组件管理
E26: 已知风险资产组件新增 | G26: 蔡云飞 | H26: 合同功能 | I26: 联调完成 | J26: 46091 | K26: 信息化资产管理/资产管理/已知风险资产组件管理 | L26: 新增按钮 | N26: V3.7.0(20260312) | O26: 待反馈 | P26: V3.8.0-beat.1 | Q26: 待反馈 | R26: V3.8.0-beat.1 | S26: 待反馈 | T26: V3.8.0-beat.1 | U26: ==VLOOKUP(E26,天津功能清单!E:G,3,FALSE) -> 已发布 | V26: 信息化资产管理/资产管理/已知风险资产组件管理
E27: 已知风险资产组件删除 | G27: 蔡云飞 | H27: 合同功能 | I27: 联调完成 | J27: 46091 | K27: 信息化资产管理/资产管理/已知风险资产组件管理 | L27: 删除按钮 | N27: V3.7.0(20260312) | O27: 待反馈 | P27: V3.8.0-beat.1 | Q27: 待反馈 | R27: V3.8.0-beat.1 | S27: 待反馈 | T27: V3.8.0-beat.1 | U27: ==VLOOKUP(E27,天津功能清单!E:G,3,FALSE) -> 已发布 | V27: 信息化资产管理/资产管理/已知风险资产组件管理
E28: 已知风险资产组件修改 | G28: 蔡云飞 | H28: 合同功能 | I28: 联调完成 | J28: 46091 | K28: 信息化资产管理/资产管理/已知风险资产组件管理 | L28: 修改按钮 | N28: V3.7.0(20260312) | O28: 待反馈 | P28: V3.8.0-beat.1 | Q28: 待反馈 | R28: V3.8.0-beat.1 | S28: 待反馈 | T28: V3.8.0-beat.1 | U28: ==VLOOKUP(E28,天津功能清单!E:G,3,FALSE) -> 已发布 | V28: 信息化资产管理/资产管理/已知风险资产组件管理
E29: 整理资产指纹、CPE库、VEX文档数据(查询) | G29: 蔡云飞 | H29: 合同功能 | I29: 联调完成 | J29: 46098 | K29: 信息化资产管理/资产管理/已知风险资产组件管理 | L29: 查询按钮 | N29: V3.8.0-beat.1 | O29: 待反馈 | P29: V3.8.0-beat.1 | Q29: 待反馈 | R29: V3.8.0-beat.1 | S29: 待反馈 | T29: V3.8.0-beat.1 | U29: ==VLOOKUP(E29,天津功能清单!E:G,3,FALSE) -> 已发布 | V29: 信息化资产管理/资产管理/已知风险资产组件管理
C30: 风险资产组件评分 | D30: 风险资产组件评分 | E30: 风险资产组件评分计算 | F30: 广东省修改功能点名字：风险资产组件评分公式计算分值 | G30: 蔡云飞 | H30: 合同功能 | I30: 联调完成 | J30: 46105 | K30: 信息化资产管理/资产管理/风险资产组件评分管理 | L30: 计算按钮 | N30: V3.8.0-beat.1 | O30: 待反馈 | P30: V3.8.0-beat.1 | Q30: 待反馈 | R30: V3.8.0-beat.1 | S30: 待反馈 | T30: V3.8.0-beat.1 | U30: ==VLOOKUP(E30,天津功能清单!E:G,3,FALSE) -> 已发布 | V30: 信息化资产管理/资产管理/风险资产组件评分管理
E31: 风险资产组件评分手动调整 | F31: 广东省修改功能点名字：风险资产组件评分修改数据 | G31: 蔡云飞 | H31: 合同功能 | I31: 联调完成 | J31: 46105 | K31: 信息化资产管理/资产管理/风险资产组件评分管理 | L31: 修改按钮 | N31: V3.8.0-beat.1 | O31: 待反馈 | P31: V3.8.0-beat.1 | Q31: 待反馈 | R31: V3.8.0-beat.1 | S31: 待反馈 | T31: V3.8.0-beat.1 | U31: ==VLOOKUP(E31,天津功能清单!E:G,3,FALSE) -> 已发布 | V31: 信息化资产管理/资产管理/风险资产组件评分管理
E32: 风险资产组件评分规则配置 | G32: 蔡云飞 | H32: 合同功能 | I32: 联调完成 | J32: 46105 | K32: 信息化资产管理/资产管理/风险资产组件评分管理 | L32: 配置按钮 | N32: V3.8.0-beat.1 | O32: 待反馈 | P32: V3.8.0-beat.1 | Q32: 待反馈 | R32: V3.8.0-beat.1 | S32: 待反馈 | T32: V3.8.0-beat.1 | U32: ==VLOOKUP(E32,天津功能清单!E:G,3,FALSE) -> 已发布 | V32: 信息化资产管理/资产管理/风险资产组件评分管理
C33: 本省字典回传与更新 | D33: 本省字典回传与更新 | E33: 未上传弱口令筛选 | G33: 仲光华 | H33: 合同功能 | I33: 联调完成 | J33: 46091 | K33: 漏洞管理平台/工单管理/系统漏洞工单 | L33: 搜索处置方式是字典组合爆破的，可以看到未回传的任务 | N33: V3.7.0(20260312) | O33: 待反馈 | P33: V3.8.0-beat.1 | Q33: 待反馈 | R33: V3.8.0-beat.1 | S33: 待反馈 | T33: V3.8.0-beat.1 | U33: ==VLOOKUP(E33,天津功能清单!E:G,3,FALSE) -> 已发布 | V33: 漏洞管理平台/工单管理/系统漏洞工单
E34: 回传弱口令 | G34: 仲光华 | H34: 合同功能 | I34: 联调完成 | J34: 46091 | K34: 漏洞管理平台/任务管理/口令字典上传任务 | L34: 选择业务场景后，点击上传按钮进行回传 | N34: V3.7.0(20260312) | O34: 待反馈 | P34: V3.8.0-beat.1 | Q34: 待反馈 | R34: V3.8.0-beat.1 | S34: 待反馈 | T34: V3.8.0-beat.1 | U34: ==VLOOKUP(E34,天津功能清单!E:G,3,FALSE) -> 已发布 | V34: 漏洞管理平台/任务管理/口令字典上传任务
A35: 产品漏洞关联分析 | B35: 产品漏洞管理应用 | C35: 漏洞关联分析 | D35: 漏洞关联分析 | E35: 创建预警专项任务 | G35: 张明峰 | H35: 合同功能 | I35: 联调完成 | J35: 46091 | K35: 漏洞管理平台/任务管理/产品漏洞预警任务 | L35: 工单详情 > 任务下发；任务详情 | N35: V3.7.0(20260312) | O35: 待反馈 | P35: V3.8.0-beat.1 | Q35: 待反馈 | R35: V3.8.0-beat.1 | S35: 待反馈 | T35: V3.8.0-beat.1 | U35: ==VLOOKUP(E35,天津功能清单!E:G,3,FALSE) -> 已发布 | V35: 漏洞管理平台/任务管理/产品漏洞预警任务
E36: 查看预警任务结果 | G36: 张明峰 | H36: 合同功能 | I36: 联调完成 | J36: 46091 | N36: V3.7.0(20260312) | O36: 待反馈 | P36: V3.8.0-beat.1 | Q36: 待反馈 | R36: V3.8.0-beat.1 | S36: 待反馈 | T36: V3.8.0-beat.1 | U36: ==VLOOKUP(E36,天津功能清单!E:G,3,FALSE) -> 已发布
C37: 修复决策支持 | D37: 修复决策支持 | E37: 查看修复决策策略 | G37: 张明峰 | H37: 合同功能 | I37: 联调完成 | J37: 46104 | K37: 运营·深耕/产品漏洞与风险识别/修复决策支持 | N37: V3.8.0-beat.1 | O37: 待反馈 | P37: V3.8.0-beat.1 | Q37: 待反馈 | R37: V3.8.0-beat.1 | S37: 待反馈 | T37: V3.8.0-beat.1 | U37: ==VLOOKUP(E37,天津功能清单!E:G,3,FALSE) -> 已发布 | V37: 漏洞生命周期管理/产品漏洞管理/修复决策支持
E38: 修改修复决策策略 | G38: 张明峰 | H38: 合同功能 | I38: 联调完成 | J38: 46104 | K38: 运营·深耕/产品漏洞与风险识别/修复决策支持 | N38: V3.8.0-beat.1 | O38: 待反馈 | P38: V3.8.0-beat.1 | Q38: 待反馈 | R38: V3.8.0-beat.1 | S38: 待反馈 | T38: V3.8.0-beat.1 | U38: ==VLOOKUP(E38,天津功能清单!E:G,3,FALSE) -> 已发布 | V38: 漏洞生命周期管理/产品漏洞管理/修复决策支持
E39: 删除修复决策策略 | G39: 张明峰 | H39: 合同功能 | I39: 联调完成 | J39: 46104 | K39: 运营·深耕/产品漏洞与风险识别/修复决策支持 | N39: V3.8.0-beat.1 | O39: 待反馈 | P39: V3.8.0-beat.1 | Q39: 待反馈 | R39: V3.8.0-beat.1 | S39: 待反馈 | T39: V3.8.0-beat.1 | U39: ==VLOOKUP(E39,天津功能清单!E:G,3,FALSE) -> 已发布 | V39: 漏洞生命周期管理/产品漏洞管理/修复决策支持
C40: 漏洞指纹排查 | D40: 漏洞指纹排查 | E40: 采集漏洞指纹 | G40: 张明峰 | H40: 合同功能 | I40: 联调完成 | J40: 46106 | K40: 信息化资产管理/资产管理/漏洞指纹管理 | L40: 漏洞扫描任务发现漏洞后，自动标准化资产组件信息同步到漏洞指纹库 | N40: V3.8.0-beat.1 | O40: 待反馈 | P40: V3.8.0-beat.1 | Q40: 待反馈 | R40: V3.8.0-beat.1 | S40: 待反馈 | T40: V3.8.0-beat.1 | U40: ==VLOOKUP(E40,天津功能清单!E:G,3,FALSE) -> 已发布 | V40: 信息化资产管理/资产管理/漏洞指纹管理
...

Sheet 2024期功能研发汇总表(河北三期)
A1: OPEX-需求名称 CAPEX-子系统 | B1: 一级模块 | C1: 二级模块 | D1: 三级模块 | E1: 功能过程 | F1: 备注 | G1: 分工 | H1: 功能项 | I1: 研发进展 | J1: 更新日期 | K1: 菜单/路径(完成必填) | L1: 功能操作 | M1: 界面截图 | N1: 是否使用模板 | P1: 菜单/路径(原始菜单审核完毕) | Q1: 部署服务名字（后端） | R1: 部署服务名字（前端）
B2: 系统漏洞风险排查 | C2: 重大漏洞专项检测考核要求 | D2: 重大漏洞专项检测工单管理 | E2: 专项检测工单下发接口 | G2: 汤凤欣 | H2: 合同功能
E3: 专项检测工单结果回传接口 | G3: 汤凤欣 | H3: 合同功能
E4: 专项检测工单查询 | G4: 汤凤欣 | H4: 合同功能 | K4: 任务工作台/运营中心/系统漏洞排查处置工单 | L4: 列表条件查询 | P4: 漏洞生命周期管理/专项任务管理/重大漏洞专项管理
E5: 专项检测工单新增 | G5: 汤凤欣 | H5: 合同功能 | K5: 任务工作台/运营中心/系统漏洞排查处置工单 | L5: 新增按钮 | P5: 漏洞生命周期管理/专项任务管理/重大漏洞专项管理
E6: 专项检测工单修改 | G6: 汤凤欣 | H6: 合同功能 | K6: 任务工作台/运营中心/系统漏洞排查处置工单 | L6: 列表修改按钮 | P6: 漏洞生命周期管理/专项任务管理/重大漏洞专项管理
E7: 专项检测工单详情查看 | G7: 汤凤欣 | H7: 合同功能 | K7: 任务工作台/运营中心/系统漏洞排查处置工单 | L7: 详情页面指令信息TAB页 工单基本信息 | P7: 漏洞生命周期管理/专项任务管理/重大漏洞专项管理
E8: 专项检测工单产品覆盖漏洞列表查看 | G8: 汤凤欣 | H8: 合同功能 | K8: 任务工作台/运营中心/系统漏洞排查处置工单 | L8: 详情页面产品漏洞信息TAB页
E9: 专项检测工单产品覆盖资产列表查看 | G9: 汤凤欣 | H9: 合同功能 | K9: 任务工作台/运营中心/系统漏洞排查处置工单 | L9: 详情页面资产信息TAB页
E10: 专项检测工单产品覆盖口令字典列表查看 | G10: 汤凤欣 | H10: 合同功能 | K10: 任务工作台/运营中心/系统漏洞排查处置工单 | L10: 详情页面口令字典信息TAB页（工单口令字典范围不为空时详情里才显示该TAB页）
E11: 专项检测工单删除 | G11: 汤凤欣 | H11: 合同功能 | P11: 漏洞生命周期管理/专项任务管理/重大漏洞专项管理
E12: 专项检测工单数据导出 | G12: 汤凤欣 | H12: 合同功能 | P12: 漏洞生命周期管理/专项任务管理/重大漏洞专项管理
E13: 专项检测工单结果模版导出 | G13: 汤凤欣 | H13: 合同功能 | P13: 漏洞生命周期管理/专项任务管理/重大漏洞专项管理
E14: 专项检测工单结果查看 | G14: 汤凤欣 | H14: 合同功能 | P14: 漏洞生命周期管理/专项任务管理/重大漏洞专项管理
E15: 专项检测工单结果导入 | G15: 汤凤欣 | H15: 合同功能 | P15: 漏洞生命周期管理/专项任务管理/重大漏洞专项管理
E16: 专项检测工单结果上报稽核 | G16: 汤凤欣 | H16: 合同功能
E17: 专项检测工单结果漏洞信息查看 | G17: 汤凤欣 | H17: 合同功能
E18: 专项检测工单结果漏洞导出 | G18: 汤凤欣 | H18: 合同功能
E19: 专项检测工单结果回传信息补全 | G19: 汤凤欣 | H19: 合同功能
E20: 专项检测工单结果回传数据上传 | G20: 汤凤欣 | H20: 合同功能
E21: 专项检测工单结果回传数据佐证材料附加 | G21: 汤凤欣 | H21: 合同功能
E22: 专项检测工单结果回传 | G22: 汤凤欣 | H22: 合同功能
E23: 专线检测工单处理方式查询 | G23: 汤凤欣 | H23: 合同功能
E24: 专线检测工单处理方式新增 | G24: 汤凤欣 | H24: 合同功能 | P24: 漏洞生命周期管理/专项任务管理/重大漏洞专项管理
E25: 专线检测工单处理方式修改 | G25: 汤凤欣 | H25: 合同功能 | P25: 漏洞生命周期管理/专项任务管理/重大漏洞专项管理
E26: 专线检测工单处理方式删除 | G26: 汤凤欣 | H26: 合同功能 | P26: 漏洞生命周期管理/专项任务管理/重大漏洞专项管理
E27: 专线检测工单处理方式导入 | G27: 汤凤欣 | H27: 合同功能 | P27: 漏洞生命周期管理/专项任务管理/重大漏洞专项管理
E28: 专线检测工单处理方式导出 | G28: 汤凤欣 | H28: 合同功能 | P28: 漏洞生命周期管理/专项任务管理/重大漏洞专项管理
E29: 专线检测工单处理方式详情查看 | G29: 汤凤欣 | H29: 合同功能 | P29: 漏洞生命周期管理/专项任务管理/重大漏洞专项管理
E30: 专线检测工单处理方式批量删除 | G30: 汤凤欣 | H30: 合同功能 | P30: 漏洞生命周期管理/专项任务管理/重大漏洞专项管理
D31: 重大漏洞专项检测任务派发 | E31: 专项检测工单基础信息查看 | G31: 汤凤欣 | H31: 合同功能 | K31: 漏洞生命周期管理-产品漏洞管理-专项任务管理 | P31: 漏洞生命周期管理-产品漏洞管理-专项任务管理
E32: 专项检测分发人员信息查询 | G32: 汤凤欣 | H32: 合同功能 | K32: 任务工作台-运营中心-系统漏洞排查处置工单 | P32: 任务工作台-运营中心-系统漏洞排查处置工单
E33: 专项检测分发任务添加 | G33: 汤凤欣 | H33: 合同功能 | K33: 任务工作台/运营中心/系统漏洞排查处置工单 | P33: 任务工作台/运营中心/系统漏洞排查处置工单
E34: 专项检测分发任务删除 | G34: 汤凤欣 | H34: 合同功能 | K34: 任务工作台/运营中心/系统漏洞排查处置工单 | P34: 任务工作台/运营中心/系统漏洞排查处置工单
E35: 专项检测分发任务汇总展示 | G35: 汤凤欣 | H35: 合同功能 | K35: 任务工作台/运营中心/系统漏洞排查处置工单 | P35: 任务工作台/运营中心/系统漏洞排查处置工单
E36: 专项检测任务列表查询 | G36: 汤凤欣 | H36: 合同功能 | K36: 任务工作台/运营中心/系统漏洞排查处置工单 | P36: 任务工作台/运营中心/系统漏洞排查处置工单
E37: 专项检测任务基础信息查看 | G37: 汤凤欣 | H37: 合同功能 | K37: 任务工作台/运营中心/系统漏洞排查处置工单 | P37: 任务工作台/运营中心/系统漏洞排查处置工单
E38: 专项检测资产范围列表查看 | G38: 汤凤欣 | H38: 合同功能 | K38: 任务工作台/运营中心/系统漏洞排查处置工单 | P38: 任务工作台/运营中心/系统漏洞排查处置工单
E39: 专项检测佐证材料列表查看 | G39: 汤凤欣 | H39: 合同功能 | K39: 任务工作台/运营中心/系统漏洞排查处置工单 | P39: 任务工作台/运营中心/系统漏洞排查处置工单
E40: 专项检测安全设备范围列表查看 | G40: 汤凤欣 | H40: 合同功能 | K40: 任务工作台/运营中心/系统漏洞排查处置工单 | P40: 任务工作台/运营中心/系统漏洞排查处置工单
...

Sheet 青海功能清单
A1: 一级模块 | B1: 二级模块 | C1: 三级模块 | D1: 功能过程 | E1: 版本标识 | F1: 交付情况 | G1: 菜单/路径(完成必填) | H1: 功能操作 | I1: 界面截图 | J1: 备注
A2: 工单指令接收及数据上报 | B2: 工单指令及上报接口报文修改 | C2: 漏洞业务场景管理 | D2: 查询自定义业务场景 | E2: ==VLOOKUP(D2,'2025期功能研发汇总表'!E:S,10,FALSE) -> 未发版 | G2: ==VLOOKUP(D2,'2025期功能研发汇总表'!E:S,7,FALSE) -> 运营·深耕/场景事务与溯源/漏洞业务场景管理 | H2: ==VLOOKUP(D2,'2025期功能研发汇总表'!E:S,8,FALSE) -> 0 | I2: ==VLOOKUP(D2,'2025期功能研发汇总表'!E:S,9,FALSE) -> 0 | J2: ==VLOOKUP(D2,'2025期功能研发汇总表'!E:S,3,FALSE) -> 汤凤欣
D3: 添加自定义业务场景 | E3: ==VLOOKUP(D3,'2025期功能研发汇总表'!E:S,10,FALSE) -> 未发版 | G3: ==VLOOKUP(D3,'2025期功能研发汇总表'!E:S,7,FALSE) -> 运营·深耕/场景事务与溯源/漏洞业务场景管理 | H3: ==VLOOKUP(D3,'2025期功能研发汇总表'!E:S,8,FALSE) -> 0 | I3: ==VLOOKUP(D3,'2025期功能研发汇总表'!E:S,9,FALSE) -> 0 | J3: ==VLOOKUP(D3,'2025期功能研发汇总表'!E:S,3,FALSE) -> 汤凤欣
D4: 编辑自定义业务场景 | E4: ==VLOOKUP(D4,'2025期功能研发汇总表'!E:S,10,FALSE) -> 未发版 | G4: ==VLOOKUP(D4,'2025期功能研发汇总表'!E:S,7,FALSE) -> 运营·深耕/场景事务与溯源/漏洞业务场景管理 | H4: ==VLOOKUP(D4,'2025期功能研发汇总表'!E:S,8,FALSE) -> 0 | I4: ==VLOOKUP(D4,'2025期功能研发汇总表'!E:S,9,FALSE) -> 0 | J4: ==VLOOKUP(D4,'2025期功能研发汇总表'!E:S,3,FALSE) -> 汤凤欣
D5: 删除自定义业务场景 | E5: ==VLOOKUP(D5,'2025期功能研发汇总表'!E:S,10,FALSE) -> 未发版 | G5: ==VLOOKUP(D5,'2025期功能研发汇总表'!E:S,7,FALSE) -> 运营·深耕/场景事务与溯源/漏洞业务场景管理 | H5: ==VLOOKUP(D5,'2025期功能研发汇总表'!E:S,8,FALSE) -> 0 | I5: ==VLOOKUP(D5,'2025期功能研发汇总表'!E:S,9,FALSE) -> 0 | J5: ==VLOOKUP(D5,'2025期功能研发汇总表'!E:S,3,FALSE) -> 汤凤欣
D6: 自定义业务场景启停 | E6: ==VLOOKUP(D6,'2025期功能研发汇总表'!E:S,10,FALSE) -> 未发版 | G6: ==VLOOKUP(D6,'2025期功能研发汇总表'!E:S,7,FALSE) -> 运营·深耕/场景事务与溯源/漏洞业务场景管理 | H6: ==VLOOKUP(D6,'2025期功能研发汇总表'!E:S,8,FALSE) -> 0 | I6: ==VLOOKUP(D6,'2025期功能研发汇总表'!E:S,9,FALSE) -> 0 | J6: ==VLOOKUP(D6,'2025期功能研发汇总表'!E:S,3,FALSE) -> 汤凤欣
D7: 业务场景数据导出 | E7: ==VLOOKUP(D7,'2025期功能研发汇总表'!E:S,10,FALSE) -> 未发版 | G7: ==VLOOKUP(D7,'2025期功能研发汇总表'!E:S,7,FALSE) -> 运营·深耕/场景事务与溯源/漏洞业务场景管理 | H7: ==VLOOKUP(D7,'2025期功能研发汇总表'!E:S,8,FALSE) -> 0 | I7: ==VLOOKUP(D7,'2025期功能研发汇总表'!E:S,9,FALSE) -> 0 | J7: ==VLOOKUP(D7,'2025期功能研发汇总表'!E:S,3,FALSE) -> 汤凤欣
D8: 配置执行流程策略 | E8: ==VLOOKUP(D8,'2025期功能研发汇总表'!E:S,10,FALSE) -> 未发版 | G8: ==VLOOKUP(D8,'2025期功能研发汇总表'!E:S,7,FALSE) -> 运营·深耕/场景事务与溯源/漏洞业务场景管理 | H8: ==VLOOKUP(D8,'2025期功能研发汇总表'!E:S,8,FALSE) -> 0 | I8: ==VLOOKUP(D8,'2025期功能研发汇总表'!E:S,9,FALSE) -> 0 | J8: ==VLOOKUP(D8,'2025期功能研发汇总表'!E:S,3,FALSE) -> 汤凤欣
C9: 场景事务关联分析 | D9: 分析漏洞场景影响 | E9: ==VLOOKUP(D9,'2025期功能研发汇总表'!E:S,10,FALSE) -> 未发版 | G9: ==VLOOKUP(D9,'2025期功能研发汇总表'!E:S,7,FALSE) -> 运营·深耕/场景事务与溯源/场景事务关联分析 | H9: ==VLOOKUP(D9,'2025期功能研发汇总表'!E:S,8,FALSE) -> 0 | I9: ==VLOOKUP(D9,'2025期功能研发汇总表'!E:S,9,FALSE) -> 0 | J9: ==VLOOKUP(D9,'2025期功能研发汇总表'!E:S,3,FALSE) -> 汤凤欣
C10: 场景风险预警 | D10: 生成漏洞风险防御建议 | E10: ==VLOOKUP(D10,'2025期功能研发汇总表'!E:S,10,FALSE) -> 未发版 | G10: ==VLOOKUP(D10,'2025期功能研发汇总表'!E:S,7,FALSE) -> 运营·深耕/场景事务与溯源/场景风险预警 | H10: ==VLOOKUP(D10,'2025期功能研发汇总表'!E:S,8,FALSE) -> 0 | I10: ==VLOOKUP(D10,'2025期功能研发汇总表'!E:S,9,FALSE) -> 0 | J10: ==VLOOKUP(D10,'2025期功能研发汇总表'!E:S,3,FALSE) -> 汤凤欣
C11: 场景事务看板 | D11: 修复失败原因漏洞统计 | E11: ==VLOOKUP(D11,'2025期功能研发汇总表'!E:S,10,FALSE) -> 未发版 | G11: ==VLOOKUP(D11,'2025期功能研发汇总表'!E:S,7,FALSE) -> 运营·深耕/场景事务与溯源/场景事务看板 | H11: ==VLOOKUP(D11,'2025期功能研发汇总表'!E:S,8,FALSE) -> 卡片视图，数值数据库可配置，配套插入更新中的chart_operation_model库里的表记录，执行select * from data_view_show where view_type = '场景事务看板' 根据现场情况 修改show_x对应的show_y 列数值 | I11: ==VLOOKUP(D11,'2025期功能研发汇总表'!E:S,9,FALSE) -> 0 | J11: ==VLOOKUP(D11,'2025期功能研发汇总表'!E:S,3,FALSE) -> 汤凤欣
D12: 入口系统漏洞数统计 | E12: ==VLOOKUP(D12,'2025期功能研发汇总表'!E:S,10,FALSE) -> 未发版 | G12: ==VLOOKUP(D12,'2025期功能研发汇总表'!E:S,7,FALSE) -> 运营·深耕/场景事务与溯源/场景事务看板 | H12: ==VLOOKUP(D12,'2025期功能研发汇总表'!E:S,8,FALSE) -> 0 | I12: ==VLOOKUP(D12,'2025期功能研发汇总表'!E:S,9,FALSE) -> 0 | J12: ==VLOOKUP(D12,'2025期功能研发汇总表'!E:S,3,FALSE) -> 汤凤欣
D13: 关联分析覆盖数统计 | E13: ==VLOOKUP(D13,'2025期功能研发汇总表'!E:S,10,FALSE) -> 未发版 | G13: ==VLOOKUP(D13,'2025期功能研发汇总表'!E:S,7,FALSE) -> 运营·深耕/场景事务与溯源/场景事务看板 | H13: ==VLOOKUP(D13,'2025期功能研发汇总表'!E:S,8,FALSE) -> 前端other工程 | I13: ==VLOOKUP(D13,'2025期功能研发汇总表'!E:S,9,FALSE) -> 0 | J13: ==VLOOKUP(D13,'2025期功能研发汇总表'!E:S,3,FALSE) -> 汤凤欣
D14: 已扫描产品漏洞统计 | E14: ==VLOOKUP(D14,'2025期功能研发汇总表'!E:S,10,FALSE) -> 未发版 | G14: ==VLOOKUP(D14,'2025期功能研发汇总表'!E:S,7,FALSE) -> 运营·深耕/场景事务与溯源/场景事务看板 | H14: ==VLOOKUP(D14,'2025期功能研发汇总表'!E:S,8,FALSE) -> 0 | I14: ==VLOOKUP(D14,'2025期功能研发汇总表'!E:S,9,FALSE) -> 0 | J14: ==VLOOKUP(D14,'2025期功能研发汇总表'!E:S,3,FALSE) -> 汤凤欣
D15: 已扫描口令字典统计 | E15: ==VLOOKUP(D15,'2025期功能研发汇总表'!E:S,10,FALSE) -> 未发版 | G15: ==VLOOKUP(D15,'2025期功能研发汇总表'!E:S,7,FALSE) -> 运营·深耕/场景事务与溯源/场景事务看板 | H15: ==VLOOKUP(D15,'2025期功能研发汇总表'!E:S,8,FALSE) -> 0 | I15: ==VLOOKUP(D15,'2025期功能研发汇总表'!E:S,9,FALSE) -> 0 | J15: ==VLOOKUP(D15,'2025期功能研发汇总表'!E:S,3,FALSE) -> 汤凤欣
D16: 应扫描产品漏洞统计 | E16: ==VLOOKUP(D16,'2025期功能研发汇总表'!E:S,10,FALSE) -> 未发版 | G16: ==VLOOKUP(D16,'2025期功能研发汇总表'!E:S,7,FALSE) -> 运营·深耕/场景事务与溯源/场景事务看板 | H16: ==VLOOKUP(D16,'2025期功能研发汇总表'!E:S,8,FALSE) -> 0 | I16: ==VLOOKUP(D16,'2025期功能研发汇总表'!E:S,9,FALSE) -> 0 | J16: ==VLOOKUP(D16,'2025期功能研发汇总表'!E:S,3,FALSE) -> 汤凤欣
D17: 应扫描口令字典统计 | E17: ==VLOOKUP(D17,'2025期功能研发汇总表'!E:S,10,FALSE) -> 未发版 | G17: ==VLOOKUP(D17,'2025期功能研发汇总表'!E:S,7,FALSE) -> 运营·深耕/场景事务与溯源/场景事务看板 | H17: ==VLOOKUP(D17,'2025期功能研发汇总表'!E:S,8,FALSE) -> 0 | I17: ==VLOOKUP(D17,'2025期功能研发汇总表'!E:S,9,FALSE) -> 0 | J17: ==VLOOKUP(D17,'2025期功能研发汇总表'!E:S,3,FALSE) -> 汤凤欣
D18: 漏洞扫描任务应覆盖资产总数统计 | E18: ==VLOOKUP(D18,'2025期功能研发汇总表'!E:S,10,FALSE) -> 未发版 | G18: ==VLOOKUP(D18,'2025期功能研发汇总表'!E:S,7,FALSE) -> 运营·深耕/场景事务与溯源/场景事务看板 | H18: ==VLOOKUP(D18,'2025期功能研发汇总表'!E:S,8,FALSE) -> 0 | I18: ==VLOOKUP(D18,'2025期功能研发汇总表'!E:S,9,FALSE) -> 0 | J18: ==VLOOKUP(D18,'2025期功能研发汇总表'!E:S,3,FALSE) -> 汤凤欣
D19: 弱口令扫描应覆盖资产数统计 | E19: ==VLOOKUP(D19,'2025期功能研发汇总表'!E:S,10,FALSE) -> 未发版 | G19: ==VLOOKUP(D19,'2025期功能研发汇总表'!E:S,7,FALSE) -> 运营·深耕/场景事务与溯源/场景事务看板 | H19: ==VLOOKUP(D19,'2025期功能研发汇总表'!E:S,8,FALSE) -> 0 | I19: ==VLOOKUP(D19,'2025期功能研发汇总表'!E:S,9,FALSE) -> 0 | J19: ==VLOOKUP(D19,'2025期功能研发汇总表'!E:S,3,FALSE) -> 汤凤欣
D20: 待验证系统漏洞统计 | E20: ==VLOOKUP(D20,'2025期功能研发汇总表'!E:S,10,FALSE) -> 未发版 | G20: ==VLOOKUP(D20,'2025期功能研发汇总表'!E:S,7,FALSE) -> 运营·深耕/场景事务与溯源/场景事务看板 | H20: ==VLOOKUP(D20,'2025期功能研发汇总表'!E:S,8,FALSE) -> 0 | I20: ==VLOOKUP(D20,'2025期功能研发汇总表'!E:S,9,FALSE) -> 0 | J20: ==VLOOKUP(D20,'2025期功能研发汇总表'!E:S,3,FALSE) -> 汤凤欣
D21: 验证有效系统漏洞数统计 | E21: ==VLOOKUP(D21,'2025期功能研发汇总表'!E:S,10,FALSE) -> 未发版 | G21: ==VLOOKUP(D21,'2025期功能研发汇总表'!E:S,7,FALSE) -> 运营·深耕/场景事务与溯源/场景事务看板 | H21: ==VLOOKUP(D21,'2025期功能研发汇总表'!E:S,8,FALSE) -> 0 | I21: ==VLOOKUP(D21,'2025期功能研发汇总表'!E:S,9,FALSE) -> 0 | J21: ==VLOOKUP(D21,'2025期功能研发汇总表'!E:S,3,FALSE) -> 汤凤欣
D22: 未排查资产数量统计 | E22: ==VLOOKUP(D22,'2025期功能研发汇总表'!E:S,10,FALSE) -> 未发版 | G22: ==VLOOKUP(D22,'2025期功能研发汇总表'!E:S,7,FALSE) -> 运营·深耕/场景事务与溯源/场景事务看板 | H22: ==VLOOKUP(D22,'2025期功能研发汇总表'!E:S,8,FALSE) -> 0 | I22: ==VLOOKUP(D22,'2025期功能研发汇总表'!E:S,9,FALSE) -> 0 | J22: ==VLOOKUP(D22,'2025期功能研发汇总表'!E:S,3,FALSE) -> 汤凤欣
D23: 未闭环系统漏洞统计 | E23: ==VLOOKUP(D23,'2025期功能研发汇总表'!E:S,10,FALSE) -> 未发版 | G23: ==VLOOKUP(D23,'2025期功能研发汇总表'!E:S,7,FALSE) -> 运营·深耕/场景事务与溯源/场景事务看板 | H23: ==VLOOKUP(D23,'2025期功能研发汇总表'!E:S,8,FALSE) -> 0 | I23: ==VLOOKUP(D23,'2025期功能研发汇总表'!E:S,9,FALSE) -> 0 | J23: ==VLOOKUP(D23,'2025期功能研发汇总表'!E:S,3,FALSE) -> 汤凤欣
... D27: 误报系统漏洞数统计 | E27: ==VLOOKUP(D27,'2025期功能研发汇总表'!E:S,10,FALSE) -> 未发版 | G27: ==VLOOKUP(D27,'2025期功能研发汇总表'!E:S,7,FALSE) -> 运营·深耕/场景事务与溯源/场景事务看板 | H27: ==VLOOKUP(D27,'2025期功能研发汇总表'!E:S,8,FALSE) -> 0 | I27: ==VLOOKUP(D27,'2025期功能研发汇总表'!E:S,9,FALSE) -> 0 | J27: ==VLOOKUP(D27,'2025期功能研发汇总表'!E:S,3,FALSE) -> 汤凤欣
C28: 效能指标度量 | D28: VPT风险等级统计 | E28: ==VLOOKUP(D28,'2025期功能研发汇总表'!E:S,10,FALSE) -> 未发版 | G28: ==VLOOKUP(D28,'2025期功能研发汇总表'!E:S,7,FALSE) -> 运营·深耕/场景事务与溯源/效能指标度量 | H28: ==VLOOKUP(D28,'2025期功能研发汇总表'!E:S,8,FALSE) -> 0 | I28: ==VLOOKUP(D28,'2025期功能研发汇总表'!E:S,9,FALSE) -> 0 | J28: ==VLOOKUP(D28,'2025期功能研发汇总表'!E:S,3,FALSE) -> 汤凤欣
D29: 产品漏洞覆盖率统计 | E29: ==VLOOKUP(D29,'2025期功能研发汇总表'!E:S,10,FALSE) -> 未发版 | G29: ==VLOOKUP(D29,'2025期功能研发汇总表'!E:S,7,FALSE) -> 运营·深耕/场景事务与溯源/效能指标度量 | H29: ==VLOOKUP(D29,'2025期功能研发汇总表'!E:S,8,FALSE) -> 0 | I29: ==VLOOKUP(D29,'2025期功能研发汇总表'!E:S,9,FALSE) -> 0 | J29: ==VLOOKUP(D29,'2025期功能研发汇总表'!E:S,3,FALSE) -> 汤凤欣
D30: 弱口令扫描检测周期统计 | E30: ==VLOOKUP(D30,'2025期功能研发汇总表'!E:S,10,FALSE) -> 未发版 | G30: ==VLOOKUP(D30,'2025期功能研发汇总表'!E:S,7,FALSE) -> 运营·深耕/场景事务与溯源/效能指标度量 | H30: ==VLOOKUP(D30,'2025期功能研发汇总表'!E:S,8,FALSE) -> 0 | I30: ==VLOOKUP(D30,'2025期功能研发汇总表'!E:S,9,FALSE) -> 0 | J30: ==VLOOKUP(D30,'2025期功能研发汇总表'!E:S,3,FALSE) -> 汤凤欣
D31: 弱口令扫描资产覆盖率统计 | E31: ==VLOOKUP(D31,'2025期功能研发汇总表'!E:S,10,FALSE) -> 未发版 | G31: ==VLOOKUP(D31,'2025期功能研发汇总表'!E:S,7,FALSE) -> 运营·深耕/场景事务与溯源/效能指标度量 | H31: ==VLOOKUP(D31,'2025期功能研发汇总表'!E:S,8,FALSE) -> 0 | I31: ==VLOOKUP(D31,'2025期功能研发汇总表'!E:S,9,FALSE) -> 0 | J31: ==VLOOKUP(D31,'2025期功能研发汇总表'!E:S,3,FALSE) -> 汤凤欣
D32: 弱口令覆盖率统计 | E32: ==VLOOKUP(D32,'2025期功能研发汇总表'!E:S,10,FALSE) -> 未发版 | G32: ==VLOOKUP(D32,'2025期功能研发汇总表'!E:S,7,FALSE) -> 运营·深耕/场景事务与溯源/效能指标度量 | H32: ==VLOOKUP(D32,'2025期功能研发汇总表'!E:S,8,FALSE) -> 0 | I32: ==VLOOKUP(D32,'2025期功能研发汇总表'!E:S,9,FALSE) -> 0 | J32: ==VLOOKUP(D32,'2025期功能研发汇总表'!E:S,3,FALSE) -> 汤凤欣
D33: 有效漏洞率统计 | E33: ==VLOOKUP(D33,'2025期功能研发汇总表'!E:S,10,FALSE) -> 未发版 | G33: ==VLOOKUP(D33,'2025期功能研发汇总表'!E:S,7,FALSE) -> 运营·深耕/场景事务与溯源/效能指标度量 | H33: ==VLOOKUP(D33,'2025期功能研发汇总表'!E:S,8,FALSE) -> 0 | I33: ==VLOOKUP(D33,'2025期功能研发汇总表'!E:S,9,FALSE) -> 0 | J33: ==VLOOKUP(D33,'2025期功能研发汇总表'!E:S,3,FALSE) -> 汤凤欣
D34: 未排查原因比例统计 | E34: ==VLOOKUP(D34,'2025期功能研发汇总表'!E:S,10,FALSE) -> 未发版 | G34: ==VLOOKUP(D34,'2025期功能研发汇总表'!E:S,7,FALSE) -> 运营·深耕/场景事务与溯源/效能指标度量 | H34: ==VLOOKUP(D34,'2025期功能研发汇总表'!E:S,8,FALSE) -> 0 | I34: ==VLOOKUP(D34,'2025期功能研发汇总表'!E:S,9,FALSE) -> 0 | J34: ==VLOOKUP(D34,'2025期功能研发汇总表'!E:S,3,FALSE) -> 汤凤欣
D35: 未闭环漏洞一致率统计 | E35: ==VLOOKUP(D35,'2025期功能研发汇总表'!E:S,10,FALSE) -> 未发版 | G35: ==VLOOKUP(D35,'2025期功能研发汇总表'!E:S,7,FALSE) -> 运营·深耕/场景事务与溯源/效能指标度量 | H35: ==VLOOKUP(D35,'2025期功能研发汇总表'!E:S,8,FALSE) -> 0 | I35: ==VLOOKUP(D35,'2025期功能研发汇总表'!E:S,9,FALSE) -> 0 | J35: ==VLOOKUP(D35,'2025期功能研发汇总表'!E:S,3,FALSE) -> 汤凤欣
D36: 漏洞修复成功率统计 | E36: ==VLOOKUP(D36,'2025期功能研发汇总表'!E:S,10,FALSE) -> 未发版 | G36: ==VLOOKUP(D36,'2025期功能研发汇总表'!E:S,7,FALSE) -> 运营·深耕/场景事务与溯源/效能指标度量 | H36: ==VLOOKUP(D36,'2025期功能研发汇总表'!E:S,8,FALSE) -> 0 | I36: ==VLOOKUP(D36,'2025期功能研发汇总表'!E:S,9,FALSE) -> 0 | J36: ==VLOOKUP(D36,'2025期功能研发汇总表'!E:S,3,FALSE) -> 汤凤欣
D37: 漏洞关联分析资产覆盖率统计 | E37: ==VLOOKUP(D37,'2025期功能研发汇总表'!E:S,10,FALSE) -> 未发版 | G37: ==VLOOKUP(D37,'2025期功能研发汇总表'!E:S,7,FALSE) -> 运营·深耕/场景事务与溯源/效能指标度量 | H37: ==VLOOKUP(D37,'2025期功能研发汇总表'!E:S,8,FALSE) -> 0 | I37: ==VLOOKUP(D37,'2025期功能研发汇总表'!E:S,9,FALSE) -> 0 | J37: ==VLOOKUP(D37,'2025期功能研发汇总表'!E:S,3,FALSE) -> 汤凤欣
D38: 漏洞初始修复率统计 | E38: ==VLOOKUP(D38,'2025期功能研发汇总表'!E:S,10,FALSE) -> 未发版 | G38: ==VLOOKUP(D38,'2025期功能研发汇总表'!E:S,7,FALSE) -> 运营·深耕/场景事务与溯源/效能指标度量 | H38: ==VLOOKUP(D38,'2025期功能研发汇总表'!E:S,8,FALSE) -> 0 | I38: ==VLOOKUP(D38,'2025期功能研发汇总表'!E:S,9,FALSE) -> 0 | J38: ==VLOOKUP(D38,'2025期功能研发汇总表'!E:S,3,FALSE) -> 汤凤欣
D39: 漏洞失败原因比例统计 | E39: ==VLOOKUP(D39,'2025期功能研发汇总表'!E:S,10,FALSE) -> 未发版 | G39: ==VLOOKUP(D39,'2025期功能研发汇总表'!E:S,7,FALSE) -> 运营·深耕/场景事务与溯源/效能指标度量 | H39: ==VLOOKUP(D39,'2025期功能研发汇总表'!E:S,8,FALSE) -> 0 | I39: ==VLOOKUP(D39,'2025期功能研发汇总表'!E:S,9,FALSE) -> 0 | J39: ==VLOOKUP(D39,'2025期功能研发汇总表'!E:S,3,FALSE) -> 汤凤欣
D40: 漏洞平均修复时间(已验证)统计 | E40: ==VLOOKUP(D40,'2025期功能研发汇总表'!E:S,10,FALSE) -> 未发版 | G40: ==VLOOKUP(D40,'2025期功能研发汇总表'!E:S,7,FALSE) -> 运营·深耕/场景事务与溯源/效能指标度量 | H40: ==VLOOKUP(D40,'2025期功能研发汇总表'!E:S,8,FALSE) -> 0 | I40: ==VLOOKUP(D40,'2025期功能研发汇总表'!E:S,9,FALSE) -> 0 | J40: ==VLOOKUP(D40,'2025期功能研发汇总表'!E:S,3,FALSE) -> 汤凤欣
... D43: 漏洞误报率统计 | E43: ==VLOOKUP(D43,'2025期功能研发汇总表'!E:S,10,FALSE) -> 未发版 | G43: ==VLOOKUP(D43,'2025期功能研发汇总表'!E:S,7,FALSE) -> 运营·深耕/场景事务与溯源/效能指标度量 | H43: ==VLOOKUP(D43,'2025期功能研发汇总表'!E:S,8,FALSE) -> 0 | I43: ==VLOOKUP(D43,'2025期功能研发汇总表'!E:S,9,FALSE) -> 0 | J43: ==VLOOKUP(D43,'2025期功能研发汇总表'!E:S,3,FALSE) -> 汤凤欣
C44: 弱口令检测任务下发与执行 | D44: 查询弱口令检测任务列表 | E44: ==VLOOKUP(D44,'2025期功能研发汇总表'!E:S,10,FALSE) -> V3.7.0(20260312) | F44: 已部署 | G44: ==VLOOKUP(D44,'2025期功能研发汇总表'!E:S,7,FALSE) -> 运营·深耕/弱口令与扫描管理/扫描任务管理/弱口令扫描 | H44: ==VLOOKUP(D44,'2025期功能研发汇总表'!E:S,8,FALSE) -> 0 | I44: ==VLOOKUP(D44,'2025期功能研发汇总表'!E:S,9,FALSE) -> ["https://docimg6.docs.qq.com/image/AgAABqoC77cB5mWmUmNL1YrFA7YKAp_K.png?w=1665&h=774",400,185] | J44: ==VLOOKUP(D44,'2025期功能研发汇总表'!E:S,3,FALSE) -> 仲光华
D45: 新增弱口令检测任务 | E45: ==VLOOKUP(D45,'2025期功能研发汇总表'!E:S,10,FALSE) -> V3.7.0(20260312) | F45: 已部署 | G45: ==VLOOKUP(D45,'2025期功能研发汇总表'!E:S,7,FALSE) -> 运营·深耕/弱口令与扫描管理/扫描任务管理/弱口令扫描 | H45: ==VLOOKUP(D45,'2025期功能研发汇总表'!E:S,8,FALSE) -> 0 | I45: ==VLOOKUP(D45,'2025期功能研发汇总表'!E:S,9,FALSE) -> 0 | J45: ==VLOOKUP(D45,'2025期功能研发汇总表'!E:S,3,FALSE) -> 仲光华
...

Sheet 山东功能清单
A1: OPEX-需求名称 CAPEX-子系统 | B1: 一级模块 | C1: 二级模块 | D1: 三级模块 | E1: 功能过程 | F1: 版本标识 | G1: 功能项 | H1: 研发状态 | I1: 负责人 | J1: 交付情况 | K1: 菜单/路径(完成必填) | L1: 功能操作 | M1: 界面截图
A2: 安全风险识别与利用分析 | B2: CPE库管理 | C2: CPE文档基础管理 | D2: CPE文档基础管理 | E2: CPE文档查询 | F2: ==VLOOKUP(E2,'2025期功能研发汇总表'!E:S,12,FALSE) -> V3.8.0-beat.1 | G2: ==VLOOKUP(E2,'2025期功能研发汇总表'!E:S,4,FALSE) -> 合同功能 | H2: ==VLOOKUP(E2,'2025期功能研发汇总表'!E:T,5,FALSE) -> 联调完成 | I2: ==VLOOKUP(E2,'2025期功能研发汇总表'!E:S,3,FALSE) -> 蔡云飞 | J2: 已交付 | K2: ==VLOOKUP(E2,'2025期功能研发汇总表'!E:S,7,FALSE) -> 漏洞生命周期管理/产品漏洞管理/CPE文档管理 | L2: ==VLOOKUP(E2,'2025期功能研发汇总表'!E:S,8,FALSE) -> 查询按钮 | M2: ok
A3: 安全风险识别与利用分析 | B3: CPE库管理 | C3: CPE文档基础管理 | D3: CPE文档基础管理 | E3: CPE文档创建 | F3: ==VLOOKUP(E3,'2025期功能研发汇总表'!E:S,12,FALSE) -> V3.8.0-beat.1 | G3: ==VLOOKUP(E3,'2025期功能研发汇总表'!E:S,4,FALSE) -> 合同功能 | H3: ==VLOOKUP(E3,'2025期功能研发汇总表'!E:T,5,FALSE) -> 联调完成 | I3: ==VLOOKUP(E3,'2025期功能研发汇总表'!E:S,3,FALSE) -> 蔡云飞 | J3: 已发布 | K3: ==VLOOKUP(E3,'2025期功能研发汇总表'!E:S,7,FALSE) -> 漏洞生命周期管理/产品漏洞管理/CPE文档管理 | L3: ==VLOOKUP(E3,'2025期功能研发汇总表'!E:S,8,FALSE) -> 创建按钮 | M3: ok
A4: 安全风险识别与利用分析 | B4: CPE库管理 | C4: CPE文档基础管理 | D4: CPE文档基础管理 | E4: CPE文档编辑 | F4: ==VLOOKUP(E4,'2025期功能研发汇总表'!E:S,12,FALSE) -> V3.8.0-beat.1 | G4: ==VLOOKUP(E4,'2025期功能研发汇总表'!E:S,4,FALSE) -> 合同功能 | H4: ==VLOOKUP(E4,'2025期功能研发汇总表'!E:T,5,FALSE) -> 联调完成 | I4: ==VLOOKUP(E4,'2025期功能研发汇总表'!E:S,3,FALSE) -> 蔡云飞 | J4: 已发布 | K4: ==VLOOKUP(E4,'2025期功能研发汇总表'!E:S,7,FALSE) -> 漏洞生命周期管理/产品漏洞管理/CPE文档管理 | L4: ==VLOOKUP(E4,'2025期功能研发汇总表'!E:S,8,FALSE) -> 编辑按钮 | M4: ok
A5: 安全风险识别与利用分析 | B5: CPE库管理 | C5: CPE文档基础管理 | D5: CPE文档基础管理 | E5: CPE文档删除 | F5: ==VLOOKUP(E5,'2025期功能研发汇总表'!E:S,12,FALSE) -> V3.8.0-beat.1 | G5: ==VLOOKUP(E5,'2025期功能研发汇总表'!E:S,4,FALSE) -> 合同功能 | H5: ==VLOOKUP(E5,'2025期功能研发汇总表'!E:T,5,FALSE) -> 联调完成 | I5: ==VLOOKUP(E5,'2025期功能研发汇总表'!E:S,3,FALSE) -> 蔡云飞 | J5: 已发布 | K5: ==VLOOKUP(E5,'2025期功能研发汇总表'!E:S,7,FALSE) -> 漏洞生命周期管理/产品漏洞管理/CPE文档管理 | L5: ==VLOOKUP(E5,'2025期功能研发汇总表'!E:S,8,FALSE) -> 删除按钮 | M5: ok
A6: 安全风险识别与利用分析 | B6: CPE库管理 | C6: CPE文档基础管理 | D6: CPE文档基础管理 | E6: CPE文档导入 | F6: ==VLOOKUP(E6,'2025期功能研发汇总表'!E:S,12,FALSE) -> V3.8.0-beat.1 | G6: ==VLOOKUP(E6,'2025期功能研发汇总表'!E:S,4,FALSE) -> 合同功能 | H6: ==VLOOKUP(E6,'2025期功能研发汇总表'!E:T,5,FALSE) -> 联调完成 | I6: ==VLOOKUP(E6,'2025期功能研发汇总表'!E:S,3,FALSE) -> 蔡云飞 | J6: 已发布 | K6: ==VLOOKUP(E6,'2025期功能研发汇总表'!E:S,7,FALSE) -> 漏洞生命周期管理/产品漏洞管理/CPE文档管理 | L6: ==VLOOKUP(E6,'2025期功能研发汇总表'!E:S,8,FALSE) -> 导入按钮 | M6: ok
A7: 安全风险识别与利用分析 | B7: CPE库管理 | C7: CPE文档基础管理 | D7: CPE文档基础管理 | E7: CPE文档导出 | F7: ==VLOOKUP(E7,'2025期功能研发汇总表'!E:S,12,FALSE) -> V3.8.0-beat.1 | G7: ==VLOOKUP(E7,'2025期功能研发汇总表'!E:S,4,FALSE) -> 合同功能 | H7: ==VLOOKUP(E7,'2025期功能研发汇总表'!E:T,5,FALSE) -> 联调完成 | I7: ==VLOOKUP(E7,'2025期功能研发汇总表'!E:S,3,FALSE) -> 蔡云飞 | J7: 已发布 | K7: ==VLOOKUP(E7,'2025期功能研发汇总表'!E:S,7,FALSE) -> 漏洞生命周期管理/产品漏洞管理/CPE文档管理 | L7: ==VLOOKUP(E7,'2025期功能研发汇总表'!E:S,8,FALSE) -> 导出按钮 | M7: ok
A8: 安全风险识别与利用分析 | B8: CPE库管理 | C8: CPE数据标准化校验 | D8: CPE数据标准化校验 | E8: CPE数据格式校验 | F8: ==VLOOKUP(E8,'2025期功能研发汇总表'!E:S,12,FALSE) -> V3.8.0-beat.1 | G8: ==VLOOKUP(E8,'2025期功能研发汇总表'!E:S,4,FALSE) -> 合同功能 | H8: ==VLOOKUP(E8,'2025期功能研发汇总表'!E:T,5,FALSE) -> 联调完成 | I8: ==VLOOKUP(E8,'2025期功能研发汇总表'!E:S,3,FALSE) -> 蔡云飞 | J8: 已发布 | K8: ==VLOOKUP(E8,'2025期功能研发汇总表'!E:S,7,FALSE) -> 漏洞生命周期管理/产品漏洞管理/CPE文档管理 | L8: ==VLOOKUP(E8,'2025期功能研发汇总表'!E:S,8,FALSE) -> 程序内部自动执行 | M8: ==VLOOKUP(E8,'2025期功能研发汇总表'!E:S,9,FALSE) -> 0
A9: 安全风险识别与利用分析 | B9: VEX文档管理 | C9: VEX文档全生命周期管理 | D9: VEX文档全生命周期管理 | E9: CISA VEX文档下载 | F9: ==VLOOKUP(E9,'2025期功能研发汇总表'!E:S,12,FALSE) -> #N/A | G9: ==VLOOKUP(E9,'2025期功能研发汇总表'!E:S,4,FALSE) -> #N/A | H9: ==VLOOKUP(E9,'2025期功能研发汇总表'!E:T,5,FALSE) -> #N/A | I9: ==VLOOKUP(E9,'2025期功能研发汇总表'!E:S,3,FALSE) -> #N/A | J9: 已发布 | K9: ==VLOOKUP(E9,'2025期功能研发汇总表'!E:S,7,FALSE) -> #N/A | L9: ==VLOOKUP(E9,'2025期功能研发汇总表'!E:S,8,FALSE) -> #N/A | M9: ==VLOOKUP(E9,'2025期功能研发汇总表'!E:S,9,FALSE) -> #N/A
A10: 安全风险识别与利用分析 | B10: VEX文档管理 | C10: VEX文档全生命周期管理 | D10: VEX文档全生命周期管理 | E10: CISA VEX文档创建 | F10: ==VLOOKUP(E10,'2025期功能研发汇总表'!E:S,12,FALSE) -> V3.8.0-beat.1 | G10: ==VLOOKUP(E10,'2025期功能研发汇总表'!E:S,4,FALSE) -> 合同功能 | H10: ==VLOOKUP(E10,'2025期功能研发汇总表'!E:T,5,FALSE) -> 联调完成 | I10: ==VLOOKUP(E10,'2025期功能研发汇总表'!E:S,3,FALSE) -> 蔡云飞 | J10: 已发布 | K10: ==VLOOKUP(E10,'2025期功能研发汇总表'!E:S,7,FALSE) -> 运营·深耕/产品漏洞与风险识别/VEX生命周期管理 | L10: ==VLOOKUP(E10,'2025期功能研发汇总表'!E:S,8,FALSE) -> 新增按钮 | M10: ==VLOOKUP(E10,'2025期功能研发汇总表'!E:S,9,FALSE) -> 0
A11: 安全风险识别与利用分析 | B11: VEX文档管理 | C11: VEX文档全生命周期管理 | D11: VEX文档全生命周期管理 | E11: CISA VEX文档删除 | F11: ==VLOOKUP(E11,'2025期功能研发汇总表'!E:S,12,FALSE) -> V3.8.0-beat.1 | G11: ==VLOOKUP(E11,'2025期功能研发汇总表'!E:S,4,FALSE) -> 合同功能 | H11: ==VLOOKUP(E11,'2025期功能研发汇总表'!E:T,5,FALSE) -> 联调完成 | I11: ==VLOOKUP(E11,'2025期功能研发汇总表'!E:S,3,FALSE) -> 蔡云飞 | J11: 已发布 | K11: ==VLOOKUP(E11,'2025期功能研发汇总表'!E:S,7,FALSE) -> 运营·深耕/产品漏洞与风险识别/VEX生命周期管理 | L11: ==VLOOKUP(E11,'2025期功能研发汇总表'!E:S,8,FALSE) -> 删除按钮 | M11: ==VLOOKUP(E11,'2025期功能研发汇总表'!E:S,9,FALSE) -> 0
A12: 安全风险识别与利用分析 | B12: VEX文档管理 | C12: VEX文档全生命周期管理 | D12: VEX文档全生命周期管理 | E12: CISA VEX文档导入 | F12: ==VLOOKUP(E12,'2025期功能研发汇总表'!E:S,12,FALSE) -> V3.8.0-beat.1 | G12: ==VLOOKUP(E12,'2025期功能研发汇总表'!E:S,4,FALSE) -> 合同功能 | H12: ==VLOOKUP(E12,'2025期功能研发汇总表'!E:T,5,FALSE) -> 联调完成 | I12: ==VLOOKUP(E12,'2025期功能研发汇总表'!E:S,3,FALSE) -> 蔡云飞 | J12: 已发布 | K12: ==VLOOKUP(E12,'2025期功能研发汇总表'!E:S,7,FALSE) -> 运营·深耕/产品漏洞与风险识别/VEX生命周期管理 | L12: ==VLOOKUP(E12,'2025期功能研发汇总表'!E:S,8,FALSE) -> 导入按钮 | M12: ==VLOOKUP(E12,'2025期功能研发汇总表'!E:S,9,FALSE) -> 0
A13: 安全风险识别与利用分析 | B13: VEX文档管理 | C13: VEX文档全生命周期管理 | D13: VEX文档全生命周期管理 | E13: CISA VEX文档导出 | F13: ==VLOOKUP(E13,'2025期功能研发汇总表'!E:S,12,FALSE) -> V3.8.0-beat.1 | G13: ==VLOOKUP(E13,'2025期功能研发汇总表'!E:S,4,FALSE) -> 合同功能 | H13: ==VLOOKUP(E13,'2025期功能研发汇总表'!E:T,5,FALSE) -> 联调完成 | I13: ==VLOOKUP(E13,'2025期功能研发汇总表'!E:S,3,FALSE) -> 蔡云飞 | J13: 已发布 | K13: ==VLOOKUP(E13,'2025期功能研发汇总表'!E:S,7,FALSE) -> 运营·深耕/产品漏洞与风险识别/VEX生命周期管理 | L13: ==VLOOKUP(E13,'2025期功能研发汇总表'!E:S,8,FALSE) -> 导出按钮 | M13: ==VLOOKUP(E13,'2025期功能研发汇总表'!E:S,9,FALSE) -> 0
A14: 安全风险识别与利用分析 | B14: VEX文档管理 | C14: VEX文档全生命周期管理 | D14: VEX文档全生命周期管理 | E14: CISA VEX文档查看 | F14: ==VLOOKUP(E14,'2025期功能研发汇总表'!E:S,12,FALSE) -> V3.8.0-beat.1 | G14: ==VLOOKUP(E14,'2025期功能研发汇总表'!E:S,4,FALSE) -> 合同功能 | H14: ==VLOOKUP(E14,'2025期功能研发汇总表'!E:T,5,FALSE) -> 联调完成 | I14: ==VLOOKUP(E14,'2025期功能研发汇总表'!E:S,3,FALSE) -> 蔡云飞 | J14: 已发布 | K14: ==VLOOKUP(E14,'2025期功能研发汇总表'!E:S,7,FALSE) -> 运营·深耕/产品漏洞与风险识别/VEX生命周期管理 | L14: ==VLOOKUP(E14,'2025期功能研发汇总表'!E:S,8,FALSE) -> 查询按钮 | M14: ==VLOOKUP(E14,'2025期功能研发汇总表'!E:S,9,FALSE) -> 0
A15: 安全风险识别与利用分析 | B15: VEX文档管理 | C15: VEX文档全生命周期管理 | D15: VEX文档全生命周期管理 | E15: CISA VEX文档编辑 | F15: ==VLOOKUP(E15,'2025期功能研发汇总表'!E:S,12,FALSE) -> V3.8.0-beat.1 | G15: ==VLOOKUP(E15,'2025期功能研发汇总表'!E:S,4,FALSE) -> 合同功能 | H15: ==VLOOKUP(E15,'2025期功能研发汇总表'!E:T,5,FALSE) -> 联调完成 | I15: ==VLOOKUP(E15,'2025期功能研发汇总表'!E:S,3,FALSE) -> 蔡云飞 | J15: 已发布 | K15: ==VLOOKUP(E15,'2025期功能研发汇总表'!E:S,7,FALSE) -> 运营·深耕/产品漏洞与风险识别/VEX生命周期管理 | L15: ==VLOOKUP(E15,'2025期功能研发汇总表'!E:S,8,FALSE) -> 修改按钮 | M15: ==VLOOKUP(E15,'2025期功能研发汇总表'!E:S,9,FALSE) -> 0
A16: 安全风险识别与利用分析 | B16: VEX文档管理 | C16: VEX文档全生命周期管理 | D16: VEX文档全生命周期管理 | E16: CISA单个VEX文档关联产品 | F16: ==VLOOKUP(E16,'2025期功能研发汇总表'!E:S,12,FALSE) -> V3.8.0-beat.1 | G16: ==VLOOKUP(E16,'2025期功能研发汇总表'!E:S,4,FALSE) -> 合同功能 | H16: ==VLOOKUP(E16,'2025期功能研发汇总表'!E:T,5,FALSE) -> 联调完成 | I16: ==VLOOKUP(E16,'2025期功能研发汇总表'!E:S,3,FALSE) -> 蔡云飞 | J16: 已发布 | K16: ==VLOOKUP(E16,'2025期功能研发汇总表'!E:S,7,FALSE) -> 运营·深耕/产品漏洞与风险识别/VEX生命周期管理 | L16: ==VLOOKUP(E16,'2025期功能研发汇总表'!E:S,8,FALSE) -> 列表关联查询展示 | M16: ==VLOOKUP(E16,'2025期功能研发汇总表'!E:S,9,FALSE) -> 0
A17: 安全风险识别与利用分析 | B17: VEX文档管理 | C17: VEX文档解析展示 | D17: VEX文档解析展示 | E17: 修改基础模板 | F17: ==VLOOKUP(E17,'2025期功能研发汇总表'!E:S,12,FALSE) -> V3.8.0-beat.1 | G17: ==VLOOKUP(E17,'2025期功能研发汇总表'!E:S,4,FALSE) -> 合同功能 | H17: ==VLOOKUP(E17,'2025期功能研发汇总表'!E:T,5,FALSE) -> 联调完成 | I17: ==VLOOKUP(E17,'2025期功能研发汇总表'!E:S,3,FALSE) -> 蔡云飞 | J17: 已发布 | K17: ==VLOOKUP(E17,'2025期功能研发汇总表'!E:S,7,FALSE) -> 运营·深耕/产品漏洞与风险识别/VEX文档解析管理 | L17: ==VLOOKUP(E17,'2025期功能研发汇总表'!E:S,8,FALSE) -> 修改按钮 | M17: ==VLOOKUP(E17,'2025期功能研发汇总表'!E:S,9,FALSE) -> 0
A18: 安全风险识别与利用分析 | B18: VEX文档管理 | C18: VEX文档解析展示 | D18: VEX文档解析展示 | E18: 删除基础模板 | F18: ==VLOOKUP(E18,'2025期功能研发汇总表'!E:S,12,FALSE) -> V3.8.0-beat.1 | G18: ==VLOOKUP(E18,'2025期功能研发汇总表'!E:S,4,FALSE) -> 合同功能 | H18: ==VLOOKUP(E18,'2025期功能研发汇总表'!E:T,5,FALSE) -> 联调完成 | I18: ==VLOOKUP(E18,'2025期功能研发汇总表'!E:S,3,FALSE) -> 蔡云飞 | J18: 已发布 | K18: ==VLOOKUP(E18,'2025期功能研发汇总表'!E:S,7,FALSE) -> 运营·深耕/产品漏洞与风险识别/VEX文档解析管理 | L18: ==VLOOKUP(E18,'2025期功能研发汇总表'!E:S,8,FALSE) -> 删除按钮 | M18: ==VLOOKUP(E18,'2025期功能研发汇总表'!E:S,9,FALSE) -> 0
A19: 安全风险识别与利用分析 | B19: VEX文档管理 | C19: VEX文档解析展示 | D19: VEX文档解析展示 | E19: 导入基础模板 | F19: ==VLOOKUP(E19,'2025期功能研发汇总表'!E:S,12,FALSE) -> V3.8.0-beat.1 | G19: ==VLOOKUP(E19,'2025期功能研发汇总表'!E:S,4,FALSE) -> 合同功能 | H19: ==VLOOKUP(E19,'2025期功能研发汇总表'!E:T,5,FALSE) -> 联调完成 | I19: ==VLOOKUP(E19,'2025期功能研发汇总表'!E:S,3,FALSE) -> 蔡云飞 | J19: 已发布 | K19: ==VLOOKUP(E19,'2025期功能研发汇总表'!E:S,7,FALSE) -> 运营·深耕/产品漏洞与风险识别/VEX文档解析管理 | L19: ==VLOOKUP(E19,'2025期功能研发汇总表'!E:S,8,FALSE) -> 导入按钮 | M19: ==VLOOKUP(E19,'2025期功能研发汇总表'!E:S,9,FALSE) -> 0
... A68: 漏洞概念验证全生命周期管理 | B68: 漏洞概念验证插件配置管理 | C68: 插件验证与审核 | D68: 插件验证与审核 | E68: 查看插件信息及其关联漏洞信息 | F68: ==VLOOKUP(E68,'2025期功能研发汇总表'!E:S,12,FALSE) -> V3.8.0-beat.1 | G68: ==VLOOKUP(E68,'2025期功能研发汇总表'!E:S,4,FALSE) -> 合同功能 | H68: ==VLOOKUP(E68,'2025期功能研发汇总表'!E:T,5,FALSE) -> 联调完成 | I68: ==VLOOKUP(E68,'2025期功能研发汇总表'!E:S,3,FALSE) -> 张明峰 | J68: 已发布 | K68: ==VLOOKUP(E68,'2025期功能研发汇总表'!E:S,7,FALSE) -> 运营·深耕/漏洞概念验证/插件本地管理 | L68: ==VLOOKUP(E68,'2025期功能研发汇总表'!E:S,8,FALSE) -> 点击列表数据漏洞ID | M68: ==VLOOKUP(E68,'2025期功能研发汇总表'!E:S,9,FALSE) -> 0
A69: 漏洞概念验证全生命周期管理 | B69: 漏洞概念验证插件配置管理 | C69: 插件验证与审核 | D69: 插件验证与审核 | E69: 人工线下初步验证插件 | F69: ==VLOOKUP(E69,'2025期功能研发汇总表'!E:S,12,FALSE) -> 未发版 | G69: ==VLOOKUP(E69,'2025期功能研发汇总表'!E:S,4,FALSE) -> 合同功能 | H69: ==VLOOKUP(E69,'2025期功能研发汇总表'!E:T,5,FALSE) -> 已废弃 | I69: ==VLOOKUP(E69,'2025期功能研发汇总表'!E:S,3,FALSE) -> 张明峰 | K69: ==VLOOKUP(E69,'2025期功能研发汇总表'!E:S,7,FALSE) -> 0 | L69: ==VLOOKUP(E69,'2025期功能研发汇总表'!E:S,8,FALSE) -> 0 | M69: ==VLOOKUP(E69,'2025期功能研发汇总表'!E:S,9,FALSE) -> 0
A70: 漏洞概念验证全生命周期管理 | B70: 漏洞概念验证插件配置管理 | C70: 插件验证与审核 | D70: 插件验证与审核 | E70: 插件基础安全性 | F70: ==VLOOKUP(E70,'2025期功能研发汇总表'!E:S,12,FALSE) -> V3.8.0-beat.2 | G70: ==VLOOKUP(E70,'2025期功能研发汇总表'!E:S,4,FALSE) -> 合同功能 | H70: ==VLOOKUP(E70,'2025期功能研发汇总表'!E:T,5,FALSE) -> 联调完成 | I70: ==VLOOKUP(E70,'2025期功能研发汇总表'!E:S,3,FALSE) -> 张明峰 | J70: 已部署 | K70: ==VLOOKUP(E70,'2025期功能研发汇总表'!E:S,7,FALSE) -> 运营·深耕/漏洞概念验证/插件验证与审核 | L70: ==VLOOKUP(E70,'2025期功能研发汇总表'!E:S,8,FALSE) -> 点击"安全检测"按钮打开界面操作 | M70: ==VLOOKUP(E70,'2025期功能研发汇总表'!E:S,9,FALSE) -> 0
A71: 漏洞概念验证全生命周期管理 | B71: 漏洞概念验证插件配置管理 | C71: 插件验证与审核 | D71: 插件验证与审核 | E71: 人工线下验证插件基础安全性 | F71: ==VLOOKUP(E71,'2025期功能研发汇总表'!E:S,12,FALSE) -> 未发版 | G71: ==VLOOKUP(E71,'2025期功能研发汇总表'!E:S,4,FALSE) -> 合同功能 | H71: ==VLOOKUP(E71,'2025期功能研发汇总表'!E:T,5,FALSE) -> 已废弃 | I71: ==VLOOKUP(E71,'2025期功能研发汇总表'!E:S,3,FALSE) -> 张明峰 | K71: ==VLOOKUP(E71,'2025期功能研发汇总表'!E:S,7,FALSE) -> 运营·深耕/漏洞概念验证/插件验证与审核 | L71: ==VLOOKUP(E71,'2025期功能研发汇总表'!E:S,8,FALSE) -> 0 | M71: ==VLOOKUP(E71,'2025期功能研发汇总表'!E:S,9,FALSE) -> 0
A72: 漏洞概念验证全生命周期管理 | B72: 漏洞概念验证插件配置管理 | C72: 插件验证与审核 | D72: 插件验证与审核 | E72: 提交到部侧漏管平台审核 | F72: ==VLOOKUP(E72,'2025期功能研发汇总表'!E:S,12,FALSE) -> V3.8.0-beat.1 | G72: ==VLOOKUP(E72,'2025期功能研发汇总表'!E:S,4,FALSE) -> 合同功能 | H72: ==VLOOKUP(E72,'2025期功能研发汇总表'!E:T,5,FALSE) -> 联调完成 | I72: ==VLOOKUP(E72,'2025期功能研发汇总表'!E:S,3,FALSE) -> 张明峰 | J72: 已发布 | K72: ==VLOOKUP(E72,'2025期功能研发汇总表'!E:S,7,FALSE) -> 运营·深耕/漏洞概念验证/插件验证与审核 | L72: ==VLOOKUP(E72,'2025期功能研发汇总表'!E:S,8,FALSE) -> 点击"提交审核"按钮打开界面操作 | M72: ==VLOOKUP(E72,'2025期功能研发汇总表'!E:S,9,FALSE) -> 0
A73: 漏洞概念验证全生命周期管理 | B73: 漏洞概念验证插件配置管理 | C73: 插件验证与审核 | D73: 插件验证与审核 | E73: 插件等级评定 | F73: ==VLOOKUP(E73,'2025期功能研发汇总表'!E:S,12,FALSE) -> V3.8.0-beat.2 | G73: ==VLOOKUP(E73,'2025期功能研发汇总表'!E:S,4,FALSE) -> 合同功能 | H73: ==VLOOKUP(E73,'2025期功能研发汇总表'!E:T,5,FALSE) -> 联调完成 | I73: ==VLOOKUP(E73,'2025期功能研发汇总表'!E:S,3,FALSE) -> 张明峰 | J73: 已部署 | K73: ==VLOOKUP(E73,'2025期功能研发汇总表'!E:S,7,FALSE) -> 运营·深耕/漏洞概念验证/插件验证与审核 | L73: ==VLOOKUP(E73,'2025期功能研发汇总表'!E:S,8,FALSE) -> 点击"等级评定"按钮打开界面操作 | M73: ==VLOOKUP(E73,'2025期功能研发汇总表'!E:S,9,FALSE) -> 0
A74: 漏洞概念验证全生命周期管理 | B74: 漏洞概念验证插件配置管理 | C74: 插件验证与审核 | D74: 插件验证与审核 | E74: 综合判定插件状态 | F74: ==VLOOKUP(E74,'2025期功能研发汇总表'!E:S,12,FALSE) -> V3.8.0-beat.2 | G74: ==VLOOKUP(E74,'2025期功能研发汇总表'!E:S,4,FALSE) -> 合同功能 | H74: ==VLOOKUP(E74,'2025期功能研发汇总表'!E:T,5,FALSE) -> 联调完成 | I74: ==VLOOKUP(E74,'2025期功能研发汇总表'!E:S,3,FALSE) -> 张明峰 | J74: 已部署 | K74: ==VLOOKUP(E74,'2025期功能研发汇总表'!E:S,7,FALSE) -> 运营·深耕/漏洞概念验证/插件验证与审核 | L74: ==VLOOKUP(E74,'2025期功能研发汇总表'!E:S,8,FALSE) -> 点击"状态判定"按钮打开界面操作 | M74: ==VLOOKUP(E74,'2025期功能研发汇总表'!E:S,9,FALSE) -> 0
A75: 漏洞概念验证全生命周期管理 | B75: 漏洞概念验证插件配置管理 | C75: 插件验证与审核 | D75: 插件验证与审核 | E75: 部侧调用企业测接口同步审核结果 | F75: ==VLOOKUP(E75,'2025期功能研发汇总表'!E:S,12,FALSE) -> V3.8.0-beat.2 | G75: ==VLOOKUP(E75,'2025期功能研发汇总表'!E:S,4,FALSE) -> 合同功能 | H75: ==VLOOKUP(E75,'2025期功能研发汇总表'!E:T,5,FALSE) -> 联调完成 | I75: ==VLOOKUP(E75,'2025期功能研发汇总表'!E:S,3,FALSE) -> 张明峰 | J75: 已部署 | K75: ==VLOOKUP(E75,'2025期功能研发汇总表'!E:S,7,FALSE) -> 运营·深耕/漏洞概念验证/插件验证与审核 | L75: ==VLOOKUP(E75,'2025期功能研发汇总表'!E:S,8,FALSE) -> 点击"同步结果"按钮打开界面操作 | M75: ==VLOOKUP(E75,'2025期功能研发汇总表'!E:S,9,FALSE) -> 0
A76: 漏洞概念验证全生命周期管理 | B76: 漏洞概念验证插件配置管理 | C76: 插件验证与审核 | D76: 插件验证与审核 | E76: 已审核插件匹配本地漏洞 | F76: ==VLOOKUP(E76,'2025期功能研发汇总表'!E:S,12,FALSE) -> 未发版 | G76: ==VLOOKUP(E76,'2025期功能研发汇总表'!E:S,4,FALSE) -> 合同功能 | H76: ==VLOOKUP(E76,'2025期功能研发汇总表'!E:T,5,FALSE) -> 已废弃 | I76: ==VLOOKUP(E76,'2025期功能研发汇总表'!E:S,3,FALSE) -> 张明峰 | K76: ==VLOOKUP(E76,'2025期功能研发汇总表'!E:S,7,FALSE) -> 运营·深耕/漏洞概念验证/插件验证与审核 | L76: ==VLOOKUP(E76,'2025期功能研发汇总表'!E:S,8,FALSE) -> 0 | M76: ==VLOOKUP(E76,'2025期功能研发汇总表'!E:S,9,FALSE) -> 0
A77: 漏洞概念验证全生命周期管理 | B77: 漏洞概念验证插件配置管理 | C77: POC插件运行管理 | D77: POC插件运行管理 | E77: 本地引擎离线导入插件 | F77: ==VLOOKUP(E77,'2025期功能研发汇总表'!E:S,12,FALSE) -> V3.8.0-beat.1 | G77: ==VLOOKUP(E77,'2025期功能研发汇总表'!E:S,4,FALSE) -> 合同功能 | H77: ==VLOOKUP(E77,'2025期功能研发汇总表'!E:T,5,FALSE) -> 联调完成 | I77: ==VLOOKUP(E77,'2025期功能研发汇总表'!E:S,3,FALSE) -> 张明峰 | J77: 已发布 | K77: ==VLOOKUP(E77,'2025期功能研发汇总表'!E:S,7,FALSE) -> 运营·深耕/漏洞概念验证/POC插件运行管理 | L77: ==VLOOKUP(E77,'2025期功能研发汇总表'!E:S,8,FALSE) -> 0 | M77: ==VLOOKUP(E77,'2025期功能研发汇总表'!E:S,9,FALSE) -> 0
A78: 漏洞概念验证全生命周期管理 | B78: 漏洞概念验证插件配置管理 | C78: POC插件运行管理 | D78: POC插件运行管理 | E78: 输入输出数据参数管理 | F78: ==VLOOKUP(E78,'2025期功能研发汇总表'!E:S,12,FALSE) -> V3.8.0-beat.1 | G78: ==VLOOKUP(E78,'2025期功能研发汇总表'!E:S,4,FALSE) -> 合同功能 | H78: ==VLOOKUP(E78,'2025期功能研发汇总表'!E:T,5,FALSE) -> 联调完成 | I78: ==VLOOKUP(E78,'2025期功能研发汇总表'!E:S,3,FALSE) -> 张明峰 | J78: 已发布 | K78: ==VLOOKUP(E78,'2025期功能研发汇总表'!E:S,7,FALSE) -> 运营·深耕/漏洞概念验证/POC插件运行管理 | L78: ==VLOOKUP(E78,'2025期功能研发汇总表'!E:S,8,FALSE) -> 0 | M78: ==VLOOKUP(E78,'2025期功能研发汇总表'!E:S,9,FALSE) -> 0
A79: 漏洞概念验证全生命周期管理 | B79: 漏洞概念验证插件配置管理 | C79: POC插件运行管理 | D79: POC插件运行管理 | E79: 用户提交POC任务 | F79: ==VLOOKUP(E79,'2025期功能研发汇总表'!E:S,12,FALSE) -> V3.8.0-beat.1 | G79: ==VLOOKUP(E79,'2025期功能研发汇总表'!E:S,4,FALSE) -> 合同功能 | H79: ==VLOOKUP(E79,'2025期功能研发汇总表'!E:T,5,FALSE) -> 联调完成 | I79: ==VLOOKUP(E79,'2025期功能研发汇总表'!E:S,3,FALSE) -> 张明峰 | J79: 已发布 | K79: ==VLOOKUP(E79,'2025期功能研发汇总表'!E:S,7,FALSE) -> 运营·深耕/漏洞概念验证/POC插件运行管理 | L79: ==VLOOKUP(E79,'2025期功能研发汇总表'!E:S,8,FALSE) -> 0 | M79: ==VLOOKUP(E79,'2025期功能研发汇总表'!E:S,9,FALSE) -> 0
A80: 漏洞概念验证全生命周期管理 | B80: 漏洞概念验证插件配置管理 | C80: POC插件运行管理 | D80: POC插件运行管理 | E80: 创建任务界面查询POC插件 | F80: ==VLOOKUP(E80,'2025期功能研发汇总表'!E:S,12,FALSE) -> V3.8.0-beat.1 | G80: ==VLOOKUP(E80,'2025期功能研发汇总表'!E:S,4,FALSE) -> 合同功能 | H80: ==VLOOKUP(E80,'2025期功能研发汇总表'!E:T,5,FALSE) -> 联调完成 | I80: ==VLOOKUP(E80,'2025期功能研发汇总表'!E:S,3,FALSE) -> 张明峰 | J80: 已发布 | K80: ==VLOOKUP(E80,'2025期功能研发汇总表'!E:S,7,FALSE) -> 运营·深耕/漏洞概念验证/POC插件运行管理 | L80: ==VLOOKUP(E80,'2025期功能研发汇总表'!E:S,8,FALSE) -> 0 | M80: ==VLOOKUP(E80,'2025期功能研发汇总表'!E:S,9,FALSE) -> 0
A81: 漏洞概念验证全生命周期管理 | B81: 漏洞概念验证插件配置管理 | C81: POC插件运行管理 | D81: POC插件运行管理 | E81: 查询产品漏洞 | F81: ==VLOOKUP(E81,'2025期功能研发汇总表'!E:S,12,FALSE) -> V3.8.0-beat.1 | G81: ==VLOOKUP(E81,'2025期功能研发汇总表'!E:S,4,FALSE) -> 合同功能 | H81: ==VLOOKUP(E81,'2025期功能研发汇总表'!E:T,5,FALSE) -> 联调完成 | I81: ==VLOOKUP(E81,'2025期功能研发汇总表'!E:S,3,FALSE) -> 张明峰 | J81: 已发布 | K81: ==VLOOKUP(E81,'2025期功能研发汇总表'!E:S,7,FALSE) -> 运营·深耕/漏洞概念验证/POC插件运行管理 | L81: ==VLOOKUP(E81,'2025期功能研发汇总表'!E:S,8,FALSE) -> 0 | M81: ==VLOOKUP(E81,'2025期功能研发汇总表'!E:S,9,FALSE) -> 0
A82: 漏洞概念验证全生命周期管理 | B82: 漏洞概念验证插件配置管理 | C82: POC插件运行管理 | D82: POC插件运行管理 | E82: 询选择任务接收人 | F82: ==VLOOKUP(E82,'2025期功能研发汇总表'!E:S,12,FALSE) -> V3.8.0-beat.1 | G82: ==VLOOKUP(E82,'2025期功能研发汇总表'!E:S,4,FALSE) -> 合同功能 | H82: ==VLOOKUP(E82,'2025期功能研发汇总表'!E:T,5,FALSE) -> 联调完成 | I82: ==VLOOKUP(E82,'2025期功能研发汇总表'!E:S,3,FALSE) -> 张明峰 | J82: 已发布 | K82: ==VLOOKUP(E82,'2025期功能研发汇总表'!E:S,7,FALSE) -> 运营·深耕/漏洞概念验证/POC插件运行管理 | L82: ==VLOOKUP(E82,'2025期功能研发汇总表'!E:S,8,FALSE) -> 0 | M82: ==VLOOKUP(E82,'2025期功能研发汇总表'!E:S,9,FALSE) -> 0
A83: 漏洞概念验证全生命周期管理 | B83: 漏洞概念验证插件配置管理 | C83: POC插件运行管理 | D83: POC插件运行管理 | E83: 查询选择资产范围 | F83: ==VLOOKUP(E83,'2025期功能研发汇总表'!E:S,12,FALSE) -> V3.8.0-beat.1 | G83: ==VLOOKUP(E83,'2025期功能研发汇总表'!E:S,4,FALSE) -> 合同功能 | H83: ==VLOOKUP(E83,'2025期功能研发汇总表'!E:T,5,FALSE) -> 联调完成 | I83: ==VLOOKUP(E83,'2025期功能研发汇总表'!E:S,3,FALSE) -> 张明峰 | J83: 已发布 | K83: ==VLOOKUP(E83,'2025期功能研发汇总表'!E:S,7,FALSE) -> 运营·深耕/漏洞概念验证/POC插件运行管理 | L83: ==VLOOKUP(E83,'2025期功能研发汇总表'!E:S,8,FALSE) -> 0 | M83: ==VLOOKUP(E83,'2025期功能研发汇总表'!E:S,9,FALSE) -> 0
A84: 漏洞概念验证全生命周期管理 | B84: 漏洞概念验证插件配置管理 | C84: POC插件运行管理 | D84: POC插件运行管理 | E84: 查询选择POC插件 | F84: ==VLOOKUP(E84,'2025期功能研发汇总表'!E:S,12,FALSE) -> V3.8.0-beat.1 | G84: ==VLOOKUP(E84,'2025期功能研发汇总表'!E:S,4,FALSE) -> 合同功能 | H84: ==VLOOKUP(E84,'2025期功能研发汇总表'!E:T,5,FALSE) -> 联调完成 | I84: ==VLOOKUP(E84,'2025期功能研发汇总表'!E:S,3,FALSE) -> 张明峰 | J84: 已发布 | K84: ==VLOOKUP(E84,'2025期功能研发汇总表'!E:S,7,FALSE) -> 运营·深耕/漏洞概念验证/POC插件运行管理 | L84: ==VLOOKUP(E84,'2025期功能研发汇总表'!E:S,8,FALSE) -> 0 | M84: ==VLOOKUP(E84,'2025期功能研发汇总表'!E:S,9,FALSE) -> 0
A85: 漏洞概念验证全生命周期管理 | B85: 漏洞概念验证插件配置管理 | C85: POC插件运行管理 | D85: POC插件运行管理 | E85: 设置扫描序列 | F85: ==VLOOKUP(E85,'2025期功能研发汇总表'!E:S,12,FALSE) -> V3.8.0-beat.1 | G85: ==VLOOKUP(E85,'2025期功能研发汇总表'!E:S,4,FALSE) -> 合同功能 | H85: ==VLOOKUP(E85,'2025期功能研发汇总表'!E:T,5,FALSE) -> 联调完成 | I85: ==VLOOKUP(E85,'2025期功能研发汇总表'!E:S,3,FALSE) -> 张明峰 | J85: 已发布 | K85: ==VLOOKUP(E85,'2025期功能研发汇总表'!E:S,7,FALSE) -> 运营·深耕/漏洞概念验证/POC插件运行管理 | L85: ==VLOOKUP(E85,'2025期功能研发汇总表'!E:S,8,FALSE) -> 0 | M85: ==VLOOKUP(E85,'2025期功能研发汇总表'!E:S,9,FALSE) -> 0
A86: 漏洞概念验证全生命周期管理 | B86: 漏洞概念验证插件配置管理 | C86: POC插件运行管理 | D86: POC插件运行管理 | E86: 任务追踪页面查看异常信息 | F86: ==VLOOKUP(E86,'2025期功能研发汇总表'!E:S,12,FALSE) -> V3.8.0-beat.1 | G86: ==VLOOKUP(E86,'2025期功能研发汇总表'!E:S,4,FALSE) -> 合同功能 | H86: ==VLOOKUP(E86,'2025期功能研发汇总表'!E:T,5,FALSE) -> 联调完成 | I86: ==VLOOKUP(E86,'2025期功能研发汇总表'!E:S,3,FALSE) -> 张明峰 | J86: 已发布 | K86: ==VLOOKUP(E86,'2025期功能研发汇总表'!E:S,7,FALSE) -> 运营·深耕/漏洞概念验证/POC插件运行管理 | L86: ==VLOOKUP(E86,'2025期功能研发汇总表'!E:S,8,FALSE) -> 0 | M86: ==VLOOKUP(E86,'2025期功能研发汇总表'!E:S,9,FALSE) -> 0
A87: 漏洞概念验证全生命周期管理 | B87: 漏洞概念验证插件配置管理 | C87: POC插件运行管理 | D87: POC插件运行管理 | E87: 任务追踪页面查看资产信息 | F87: ==VLOOKUP(E87,'2025期功能研发汇总表'!E:S,12,FALSE) -> V3.8.0-beat.1 | G87: ==VLOOKUP(E87,'2025期功能研发汇总表'!E:S,4,FALSE) -> 合同功能 | H87: ==VLOOKUP(E87,'2025期功能研发汇总表'!E:T,5,FALSE) -> 联调完成 | I87: ==VLOOKUP(E87,'2025期功能研发汇总表'!E:S,3,FALSE) -> 张明峰 | J87: 已发布 | K87: ==VLOOKUP(E87,'2025期功能研发汇总表'!E:S,7,FALSE) -> 运营·深耕/漏洞概念验证/POC插件运行管理 | L87: ==VLOOKUP(E87,'2025期功能研发汇总表'!E:S,8,FALSE) -> 0 | M87: ==VLOOKUP(E87,'2025期功能研发汇总表'!E:S,9,FALSE) -> 0
A88: 漏洞概念验证全生命周期管理 | B88: 漏洞概念验证插件配置管理 | C88: POC插件运行管理 | D88: POC插件运行管理 | E88: 任务追踪页面查看漏洞信息 | F88: ==VLOOKUP(E88,'2025期功能研发汇总表'!E:S,12,FALSE) -> V3.8.0-beat.1 | G88: ==VLOOKUP(E88,'2025期功能研发汇总表'!E:S,4,FALSE) -> 合同功能 | H88: ==VLOOKUP(E88,'2025期功能研发汇总表'!E:T,5,FALSE) -> 联调完成 | I88: ==VLOOKUP(E88,'2025期功能研发汇总表'!E:S,3,FALSE) -> 张明峰 | J88: 已发布 | K88: ==VLOOKUP(E88,'2025期功能研发汇总表'!E:S,7,FALSE) -> 运营·深耕/漏洞概念验证/POC插件运行管理 | L88: ==VLOOKUP(E88,'2025期功能研发汇总表'!E:S,8,FALSE) -> 0 | M88: ==VLOOKUP(E88,'2025期功能研发汇总表'!E:S,9,FALSE) -> 0
...

Sheet 吉林功能清单
A1: 客户需求 | B1: 一级模块 | C1: 二级模块 | D1: 三级模块 | E1: 功能过程 | F1: 版本标识 | G1: 交付情况 | H1: 菜单/路径(完成必填) | I1: 功能操作 | J1: 界面截图 | K1: 备注
A2: 中国移动天津公司2025年漏洞管理平台提升改造项目 | B2: 安全风险识别与利用分析 | C2: CPE库管理 | D2: CPE文档基础管理 | E2: CPE文档查询 | F2: ==VLOOKUP(E2,'2025期功能研发汇总表'!E:S,10,FALSE) -> V3.8.0-beat.1 | G2: 已交付 | H2: ==VLOOKUP(E2,'2025期功能研发汇总表'!E:S,7,FALSE) -> 漏洞生命周期管理/产品漏洞管理/CPE文档管理 | I2: ==VLOOKUP(E2,'2025期功能研发汇总表'!E:S,8,FALSE) -> 查询按钮 | J2: ==VLOOKUP(E2,'2025期功能研发汇总表'!E:S,9,FALSE) -> 0 | K2: ==VLOOKUP(E2,'2025期功能研发汇总表'!E:S,3,FALSE) -> 蔡云飞
E3: CPE文档创建 | F3: ==VLOOKUP(E3,'2025期功能研发汇总表'!E:S,10,FALSE) -> V3.7.0(20260312) | G3: 已发布 | H3: ==VLOOKUP(E3,'2025期功能研发汇总表'!E:S,7,FALSE) -> 漏洞生命周期管理/产品漏洞管理/CPE文档管理 | I3: ==VLOOKUP(E3,'2025期功能研发汇总表'!E:S,8,FALSE) -> 创建按钮 | J3: ==VLOOKUP(E3,'2025期功能研发汇总表'!E:S,9,FALSE) -> 0 | K3: ==VLOOKUP(E3,'2025期功能研发汇总表'!E:S,3,FALSE) -> 蔡云飞
E4: CPE文档编辑 | F4: ==VLOOKUP(E4,'2025期功能研发汇总表'!E:S,10,FALSE) -> V3.7.0(20260312) | G4: 已发布 | H4: ==VLOOKUP(E4,'2025期功能研发汇总表'!E:S,7,FALSE) -> 漏洞生命周期管理/产品漏洞管理/CPE文档管理 | I4: ==VLOOKUP(E4,'2025期功能研发汇总表'!E:S,8,FALSE) -> 编辑按钮 | J4: ==VLOOKUP(E4,'2025期功能研发汇总表'!E:S,9,FALSE) -> 0 | K4: ==VLOOKUP(E4,'2025期功能研发汇总表'!E:S,3,FALSE) -> 蔡云飞
E5: CPE文档删除 | F5: ==VLOOKUP(E5,'2025期功能研发汇总表'!E:S,10,FALSE) -> V3.7.0(20260312) | G5: 已发布 | H5: ==VLOOKUP(E5,'2025期功能研发汇总表'!E:S,7,FALSE) -> 漏洞生命周期管理/产品漏洞管理/CPE文档管理 | I5: ==VLOOKUP(E5,'2025期功能研发汇总表'!E:S,8,FALSE) -> 删除按钮 | J5: ==VLOOKUP(E5,'2025期功能研发汇总表'!E:S,9,FALSE) -> 0 | K5: ==VLOOKUP(E5,'2025期功能研发汇总表'!E:S,3,FALSE) -> 蔡云飞
E6: CPE文档导入 | F6: ==VLOOKUP(E6,'2025期功能研发汇总表'!E:S,10,FALSE) -> V3.7.0(20260312) | G6: 已发布 | H6: ==VLOOKUP(E6,'2025期功能研发汇总表'!E:S,7,FALSE) -> 漏洞生命周期管理/产品漏洞管理/CPE文档管理 | I6: ==VLOOKUP(E6,'2025期功能研发汇总表'!E:S,8,FALSE) -> 导入按钮 | J6: ==VLOOKUP(E6,'2025期功能研发汇总表'!E:S,9,FALSE) -> 0 | K6: ==VLOOKUP(E6,'2025期功能研发汇总表'!E:S,3,FALSE) -> 蔡云飞
E7: CPE文档导出 | F7: ==VLOOKUP(E7,'2025期功能研发汇总表'!E:S,10,FALSE) -> V3.7.0(20260312) | G7: 已发布 | H7: ==VLOOKUP(E7,'2025期功能研发汇总表'!E:S,7,FALSE) -> 漏洞生命周期管理/产品漏洞管理/CPE文档管理 | I7: ==VLOOKUP(E7,'2025期功能研发汇总表'!E:S,8,FALSE) -> 导出按钮 | J7: ==VLOOKUP(E7,'2025期功能研发汇总表'!E:S,9,FALSE) -> 0 | K7: ==VLOOKUP(E7,'2025期功能研发汇总表'!E:S,3,FALSE) -> 蔡云飞
D8: CPE数据标准化校验 | E8: CPE数据格式校验 | F8: ==VLOOKUP(E8,'2025期功能研发汇总表'!E:S,10,FALSE) -> V3.7.0(20260312) | G8: 已发布 | H8: ==VLOOKUP(E8,'2025期功能研发汇总表'!E:S,7,FALSE) -> 漏洞生命周期管理/产品漏洞管理/CPE文档管理 | I8: ==VLOOKUP(E8,'2025期功能研发汇总表'!E:S,8,FALSE) -> 程序内部自动执行 | J8: ==VLOOKUP(E8,'2025期功能研发汇总表'!E:S,9,FALSE) -> 0 | K8: ==VLOOKUP(E8,'2025期功能研发汇总表'!E:S,3,FALSE) -> 蔡云飞
C9: VEX文档管理 | D9: VEX文档全生命周期管理 | E9: CISA VEX文档下载 | F9: ==VLOOKUP(E9,'2025期功能研发汇总表'!E:S,10,FALSE) -> #N/A | G9: 已发布 | H9: ==VLOOKUP(E9,'2025期功能研发汇总表'!E:S,7,FALSE) -> #N/A | I9: ==VLOOKUP(E9,'2025期功能研发汇总表'!E:S,8,FALSE) -> #N/A | J9: ==VLOOKUP(E9,'2025期功能研发汇总表'!E:S,9,FALSE) -> #N/A | K9: ==VLOOKUP(E9,'2025期功能研发汇总表'!E:S,3,FALSE) -> #N/A
E10: CISA VEX文档创建 | F10: ==VLOOKUP(E10,'2025期功能研发汇总表'!E:S,10,FALSE) -> V3.8.0-beat.1 | G10: 已发布 | H10: ==VLOOKUP(E10,'2025期功能研发汇总表'!E:S,7,FALSE) -> 运营·深耕/产品漏洞与风险识别/VEX生命周期管理 | I10: ==VLOOKUP(E10,'2025期功能研发汇总表'!E:S,8,FALSE) -> 新增按钮 | J10: ==VLOOKUP(E10,'2025期功能研发汇总表'!E:S,9,FALSE) -> 0 | K10: ==VLOOKUP(E10,'2025期功能研发汇总表'!E:S,3,FALSE) -> 蔡云飞
E11: CISA VEX文档删除 | F11: ==VLOOKUP(E11,'2025期功能研发汇总表'!E:S,10,FALSE) -> V3.8.0-beat.1 | G11: 已发布 | H11: ==VLOOKUP(E11,'2025期功能研发汇总表'!E:S,7,FALSE) -> 运营·深耕/产品漏洞与风险识别/VEX生命周期管理 | I11: ==VLOOKUP(E11,'2025期功能研发汇总表'!E:S,8,FALSE) -> 删除按钮 | J11: ==VLOOKUP(E11,'2025期功能研发汇总表'!E:S,9,FALSE) -> 0 | K11: ==VLOOKUP(E11,'2025期功能研发汇总表'!E:S,3,FALSE) -> 蔡云飞
E12: CISA VEX文档导入 | F12: ==VLOOKUP(E12,'2025期功能研发汇总表'!E:S,10,FALSE) -> V3.8.0-beat.1 | G12: 已发布 | H12: ==VLOOKUP(E12,'2025期功能研发汇总表'!E:S,7,FALSE) -> 运营·深耕/产品漏洞与风险识别/VEX生命周期管理 | I12: ==VLOOKUP(E12,'2025期功能研发汇总表'!E:S,8,FALSE) -> 导入按钮 | J12: ==VLOOKUP(E12,'2025期功能研发汇总表'!E:S,9,FALSE) -> 0 | K12: ==VLOOKUP(E12,'2025期功能研发汇总表'!E:S,3,FALSE) -> 蔡云飞
E13: CISA VEX文档导出 | F13: ==VLOOKUP(E13,'2025期功能研发汇总表'!E:S,10,FALSE) -> V3.8.0-beat.1 | G13: 已发布 | H13: ==VLOOKUP(E13,'2025期功能研发汇总表'!E:S,7,FALSE) -> 运营·深耕/产品漏洞与风险识别/VEX生命周期管理 | I13: ==VLOOKUP(E13,'2025期功能研发汇总表'!E:S,8,FALSE) -> 导出按钮 | J13: ==VLOOKUP(E13,'2025期功能研发汇总表'!E:S,9,FALSE) -> 0 | K13: ==VLOOKUP(E13,'2025期功能研发汇总表'!E:S,3,FALSE) -> 蔡云飞
E14: CISA VEX文档查看 | F14: ==VLOOKUP(E14,'2025期功能研发汇总表'!E:S,10,FALSE) -> V3.8.0-beat.1 | G14: 已发布 | H14: ==VLOOKUP(E14,'2025期功能研发汇总表'!E:S,7,FALSE) -> 运营·深耕/产品漏洞与风险识别/VEX生命周期管理 | I14: ==VLOOKUP(E14,'2025期功能研发汇总表'!E:S,8,FALSE) -> 查询按钮 | J14: ==VLOOKUP(E14,'2025期功能研发汇总表'!E:S,9,FALSE) -> 0 | K14: ==VLOOKUP(E14,'2025期功能研发汇总表'!E:S,3,FALSE) -> 蔡云飞
E15: CISA VEX文档编辑 | F15: ==VLOOKUP(E15,'2025期功能研发汇总表'!E:S,10,FALSE) -> V3.8.0-beat.1 | G15: 已发布 | H15: ==VLOOKUP(E15,'2025期功能研发汇总表'!E:S,7,FALSE) -> 运营·深耕/产品漏洞与风险识别/VEX生命周期管理 | I15: ==VLOOKUP(E15,'2025期功能研发汇总表'!E:S,8,FALSE) -> 修改按钮 | J15: ==VLOOKUP(E15,'2025期功能研发汇总表'!E:S,9,FALSE) -> 0 | K15: ==VLOOKUP(E15,'2025期功能研发汇总表'!E:S,3,FALSE) -> 蔡云飞
E16: CISA单个VEX文档关联产品 | F16: ==VLOOKUP(E16,'2025期功能研发汇总表'!E:S,10,FALSE) -> V3.8.0-beat.1 | G16: 已发布 | H16: ==VLOOKUP(E16,'2025期功能研发汇总表'!E:S,7,FALSE) -> 运营·深耕/产品漏洞与风险识别/VEX生命周期管理 | I16: ==VLOOKUP(E16,'2025期功能研发汇总表'!E:S,8,FALSE) -> 列表关联查询展示 | J16: ==VLOOKUP(E16,'2025期功能研发汇总表'!E:S,9,FALSE) -> 0 | K16: ==VLOOKUP(E16,'2025期功能研发汇总表'!E:S,3,FALSE) -> 蔡云飞
D17: VEX文档解析展示 | E17: 修改基础模板 | F17: ==VLOOKUP(E17,'2025期功能研发汇总表'!E:S,10,FALSE) -> V3.7.0(20260312) | G17: 已发布 | H17: ==VLOOKUP(E17,'2025期功能研发汇总表'!E:S,7,FALSE) -> 运营·深耕/产品漏洞与风险识别/VEX文档解析管理 | I17: ==VLOOKUP(E17,'2025期功能研发汇总表'!E:S,8,FALSE) -> 修改按钮 | J17: ==VLOOKUP(E17,'2025期功能研发汇总表'!E:S,9,FALSE) -> 0 | K17: ==VLOOKUP(E17,'2025期功能研发汇总表'!E:S,3,FALSE) -> 蔡云飞
E18: 删除基础模板 | F18: ==VLOOKUP(E18,'2025期功能研发汇总表'!E:S,10,FALSE) -> V3.7.0(20260312) | G18: 已发布 | H18: ==VLOOKUP(E18,'2025期功能研发汇总表'!E:S,7,FALSE) -> 运营·深耕/产品漏洞与风险识别/VEX文档解析管理 | I18: ==VLOOKUP(E18,'2025期功能研发汇总表'!E:S,8,FALSE) -> 删除按钮 | J18: ==VLOOKUP(E18,'2025期功能研发汇总表'!E:S,9,FALSE) -> 0 | K18: ==VLOOKUP(E18,'2025期功能研发汇总表'!E:S,3,FALSE) -> 蔡云飞
E19: 导入基础模板 | F19: ==VLOOKUP(E19,'2025期功能研发汇总表'!E:S,10,FALSE) -> V3.7.0(20260312) | G19: 已发布 | H19: ==VLOOKUP(E19,'2025期功能研发汇总表'!E:S,7,FALSE) -> 运营·深耕/产品漏洞与风险识别/VEX文档解析管理 | I19: ==VLOOKUP(E19,'2025期功能研发汇总表'!E:S,8,FALSE) -> 导入按钮 | J19: ==VLOOKUP(E19,'2025期功能研发汇总表'!E:S,9,FALSE) -> 0 | K19: ==VLOOKUP(E19,'2025期功能研发汇总表'!E:S,3,FALSE) -> 蔡云飞
E20: 导出基础模板 | F20: ==VLOOKUP(E20,'2025期功能研发汇总表'!E:S,10,FALSE) -> V3.7.0(20260312) | G20: 已发布 | H20: ==VLOOKUP(E20,'2025期功能研发汇总表'!E:S,7,FALSE) -> 运营·深耕/产品漏洞与风险识别/VEX文档解析管理 | I20: ==VLOOKUP(E20,'2025期功能研发汇总表'!E:S,8,FALSE) -> 导出按钮 | J20: ==VLOOKUP(E20,'2025期功能研发汇总表'!E:S,9,FALSE) -> 0 | K20: ==VLOOKUP(E20,'2025期功能研发汇总表'!E:S,3,FALSE) -> 蔡云飞
E21: 查询基础模板 | F21: ==VLOOKUP(E21,'2025期功能研发汇总表'!E:S,10,FALSE) -> V3.7.0(20260312) | G21: 已发布 | H21: ==VLOOKUP(E21,'2025期功能研发汇总表'!E:S,7,FALSE) -> 运营·深耕/产品漏洞与风险识别/VEX文档解析管理 | I21: ==VLOOKUP(E21,'2025期功能研发汇总表'!E:S,8,FALSE) -> 查询按钮 | J21: ==VLOOKUP(E21,'2025期功能研发汇总表'!E:S,9,FALSE) -> 0 | K21: ==VLOOKUP(E21,'2025期功能研发汇总表'!E:S,3,FALSE) -> 蔡云飞
E22: 添加基础模板 | F22: ==VLOOKUP(E22,'2025期功能研发汇总表'!E:S,10,FALSE) -> V3.7.0(20260312) | G22: 已发布 | H22: ==VLOOKUP(E22,'2025期功能研发汇总表'!E:S,7,FALSE) -> 运营·深耕/产品漏洞与风险识别/VEX文档解析管理 | I22: ==VLOOKUP(E22,'2025期功能研发汇总表'!E:S,8,FALSE) -> 新增按钮 | J22: ==VLOOKUP(E22,'2025期功能研发汇总表'!E:S,9,FALSE) -> 0 | K22: ==VLOOKUP(E22,'2025期功能研发汇总表'!E:S,3,FALSE) -> 蔡云飞
D23: VEX合规性自动化检测 | E23: 问题文档拦截 | F23: ==VLOOKUP(E23,'2025期功能研发汇总表'!E:S,10,FALSE) -> V3.7.0(20260312) | G23: 已发布 | H23: ==VLOOKUP(E23,'2025期功能研发汇总表'!E:S,7,FALSE) -> 运营·深耕/产品漏洞与风险识别/VEX文档解析管理 | I23: ==VLOOKUP(E23,'2025期功能研发汇总表'!E:S,8,FALSE) -> 程序内部自动检测执行 | J23: ==VLOOKUP(E23,'2025期功能研发汇总表'!E:S,9,FALSE) -> 0 | K23: ==VLOOKUP(E23,'2025期功能研发汇总表'!E:S,3,FALSE) -> 蔡云飞
C24: 风险组件库管理 | D24: 已知风险资产组件管理 | E24: 已知风险资产组件查询 | F24: ==VLOOKUP(E24,'2025期功能研发汇总表'!E:S,10,FALSE) -> V3.7.0(20260312) | G24: 已发布 | H24: ==VLOOKUP(E24,'2025期功能研发汇总表'!E:S,7,FALSE) -> 信息化资产管理/资产管理/已知风险资产组件管理 | I24: ==VLOOKUP(E24,'2025期功能研发汇总表'!E:S,8,FALSE) -> 查询按钮 | J24: ==VLOOKUP(E24,'2025期功能研发汇总表'!E:S,9,FALSE) -> 0 | K24: ==VLOOKUP(E24,'2025期功能研发汇总表'!E:S,3,FALSE) -> 蔡云飞
E25: 已知风险资产组件新增 | F25: ==VLOOKUP(E25,'2025期功能研发汇总表'!E:S,10,FALSE) -> V3.7.0(20260312) | G25: 已发布 | H25: ==VLOOKUP(E25,'2025期功能研发汇总表'!E:S,7,FALSE) -> 信息化资产管理/资产管理/已知风险资产组件管理 | I25: ==VLOOKUP(E25,'2025期功能研发汇总表'!E:S,8,FALSE) -> 新增按钮 | J25: ==VLOOKUP(E25,'2025期功能研发汇总表'!E:S,9,FALSE) -> 0 | K25: ==VLOOKUP(E25,'2025期功能研发汇总表'!E:S,3,FALSE) -> 蔡云飞
E26: 已知风险资产组件删除 | F26: ==VLOOKUP(E26,'2025期功能研发汇总表'!E:S,10,FALSE) -> V3.7.0(20260312) | G26: 已发布 | H26: ==VLOOKUP(E26,'2025期功能研发汇总表'!E:S,7,FALSE) -> 信息化资产管理/资产管理/已知风险资产组件管理 | I26: ==VLOOKUP(E26,'2025期功能研发汇总表'!E:S,8,FALSE) -> 删除按钮 | J26: ==VLOOKUP(E26,'2025期功能研发汇总表'!E:S,9,FALSE) -> 0 | K26: ==VLOOKUP(E26,'2025期功能研发汇总表'!E:S,3,FALSE) -> 蔡云飞
E27: 已知风险资产组件修改 | F27: ==VLOOKUP(E27,'2025期功能研发汇总表'!E:S,10,FALSE) -> V3.7.0(20260312) | G27: 已发布 | H27: ==VLOOKUP(E27,'2025期功能研发汇总表'!E:S,7,FALSE) -> 信息化资产管理/资产管理/已知风险资产组件管理 | I27: ==VLOOKUP(E27,'2025期功能研发汇总表'!E:S,8,FALSE) -> 修改按钮 | J27: ==VLOOKUP(E27,'2025期功能研发汇总表'!E:S,9,FALSE) -> 0 | K27: ==VLOOKUP(E27,'2025期功能研发汇总表'!E:S,3,FALSE) -> 蔡云飞
E28: 整理资产指纹、CPE库、VEX文档数据(查询) | F28: ==VLOOKUP(E28,'2025期功能研发汇总表'!E:S,10,FALSE) -> V3.8.0-beat.1 | G28: 已发布 | H28: ==VLOOKUP(E28,'2025期功能研发汇总表'!E:S,7,FALSE) -> 信息化资产管理/资产管理/已知风险资产组件管理 | I28: ==VLOOKUP(E28,'2025期功能研发汇总表'!E:S,8,FALSE) -> 查询按钮 | J28: ==VLOOKUP(E28,'2025期功能研发汇总表'!E:S,9,FALSE) -> 0 | K28: ==VLOOKUP(E28,'2025期功能研发汇总表'!E:S,3,FALSE) -> 蔡云飞
D29: 风险资产组件评分 | E29: 风险资产组件评分计算 | F29: ==VLOOKUP(E29,'2025期功能研发汇总表'!E:S,10,FALSE) -> V3.8.0-beat.1 | G29: 已发布 | H29: ==VLOOKUP(E29,'2025期功能研发汇总表'!E:S,7,FALSE) -> 信息化资产管理/资产管理/风险资产组件评分管理 | I29: ==VLOOKUP(E29,'2025期功能研发汇总表'!E:S,8,FALSE) -> 计算按钮 | J29: ==VLOOKUP(E29,'2025期功能研发汇总表'!E:S,9,FALSE) -> 0 | K29: ==VLOOKUP(E29,'2025期功能研发汇总表'!E:S,3,FALSE) -> 蔡云飞
E30: 风险资产组件评分手动调整 | F30: ==VLOOKUP(E30,'2025期功能研发汇总表'!E:S,10,FALSE) -> V3.8.0-beat.1 | G30: 已发布 | H30: ==VLOOKUP(E30,'2025期功能研发汇总表'!E:S,7,FALSE) -> 信息化资产管理/资产管理/风险资产组件评分管理 | I30: ==VLOOKUP(E30,'2025期功能研发汇总表'!E:S,8,FALSE) -> 修改按钮 | J30: ==VLOOKUP(E30,'2025期功能研发汇总表'!E:S,9,FALSE) -> 0 | K30: ==VLOOKUP(E30,'2025期功能研发汇总表'!E:S,3,FALSE) -> 蔡云飞
E31: 风险资产组件评分规则配置 | F31: ==VLOOKUP(E31,'2025期功能研发汇总表'!E:S,10,FALSE) -> V3.8.0-beat.1 | G31: 已发布 | H31: ==VLOOKUP(E31,'2025期功能研发汇总表'!E:S,7,FALSE) -> 信息化资产管理/资产管理/风险资产组件评分管理 | I31: ==VLOOKUP(E31,'2025期功能研发汇总表'!E:S,8,FALSE) -> 配置按钮 | J31: ==VLOOKUP(E31,'2025期功能研发汇总表'!E:S,9,FALSE) -> 0 | K31: ==VLOOKUP(E31,'2025期功能研发汇总表'!E:S,3,FALSE) -> 蔡云飞
C32: 弱口令字典库管理 | D32: 口令字典接收与同步 | E32: 接收口令字典 | F32: ==VLOOKUP(E32,'2025期功能研发汇总表'!E:S,10,FALSE) -> V3.7.0(20260312) | G32: 已发布 | H32: ==VLOOKUP(E32,'2025期功能研发汇总表'!E:S,7,FALSE) -> 漏洞管理平台/工单管理/系统漏洞工单 | I32: ==VLOOKUP(E32,'2025期功能研发汇总表'!E:S,8,FALSE) -> 弱口令的工单，可以同步至弱口令管理页面，以便同步至扫描器 | J32: ==VLOOKUP(E32,'2025期功能研发汇总表'!E:S,9,FALSE) -> ["https://docimg2.docs.qq.com/image/AgAABqoC77fz5Pb9rbxOuIl0OUEAcGGP.png?w=1674&h=774",400,184] | K32: ==VLOOKUP(E32,'2025期功能研发汇总表'!E:S,3,FALSE) -> 仲光华
E33: 同步口令字典 | F33: ==VLOOKUP(E33,'2025期功能研发汇总表'!E:S,10,FALSE) -> V3.7.0(20260312) | G33: 已发布 | H33: ==VLOOKUP(E33,'2025期功能研发汇总表'!E:S,7,FALSE) -> 运营·深耕/弱口令与扫描管理 | I33: ==VLOOKUP(E33,'2025期功能研发汇总表'!E:S,8,FALSE) -> 0 | J33: ==VLOOKUP(E33,'2025期功能研发汇总表'!E:S,9,FALSE) -> ["https://docimg9.docs.qq.com/image/AgAABqoC77d-6wotv31KcaXA51pk6VdU.png?w=1682&h=775",400,184] | K33: ==VLOOKUP(E33,'2025期功能研发汇总表'!E:S,3,FALSE) -> 仲光华
